DEBUG:asyncio: Using selector: EpollSelector (2018-08-27 01:35:59; selector_events.py:65)
DEBUG:asyncio: Using selector: EpollSelector (2018-08-27 01:36:05; selector_events.py:65)
DEBUG:asyncio: Using selector: EpollSelector (2018-08-27 01:36:59; selector_events.py:65)
DEBUG:asyncio: Using selector: EpollSelector (2018-08-27 01:37:00; selector_events.py:65)
INFO:daphne.server: HTTP/2 support enabled (2018-08-27 01:37:02; server.py:103)
INFO:daphne.server: Configuring endpoint tcp:port=8000:interface=0.0.0.0 (2018-08-27 01:37:02; server.py:112)
INFO:daphne.server: Listening on TCP address 0.0.0.0:8000 (2018-08-27 01:37:02; server.py:143)
DEBUG:asyncio: Using selector: EpollSelector (2018-08-27 02:11:08; selector_events.py:65)
INFO:daphne.server: HTTP/2 support enabled (2018-08-27 02:11:11; server.py:103)
INFO:daphne.server: Configuring endpoint tcp:port=8000:interface=0.0.0.0 (2018-08-27 02:11:11; server.py:112)
INFO:daphne.server: Listening on TCP address 0.0.0.0:8000 (2018-08-27 02:11:11; server.py:143)
WARNING:daphne.server: Application instance <Task pending coro=<AsgiHandler.__call__() running at /home/troll/.local/share/virtualenvs/backend-ArvMLrc1/lib/python3.6/site-packages/channels/http.py:180> wait_for=<Future pending cb=[<TaskWakeupMethWrapper object at 0x7f43cdc842b8>()]>> for connection <WebRequest at 0x7f43cdc96b38 method=POST uri=/auth/does-email-exist/ clientproto=HTTP/1.1> took too long to shut down and was killed. (2018-08-27 02:14:28; server.py:223)
WARNING:daphne.server: Application instance <Task pending coro=<AsgiHandler.__call__() running at /home/troll/.local/share/virtualenvs/backend-ArvMLrc1/lib/python3.6/site-packages/channels/http.py:180> wait_for=<Future pending cb=[<TaskWakeupMethWrapper object at 0x7f43cc445108>()]>> for connection <WebRequest at 0x7f43cc3dab00 method=POST uri=/auth/does-email-exist/ clientproto=HTTP/1.1> took too long to shut down and was killed. (2018-08-27 02:15:02; server.py:223)
DEBUG:jwt_auth.views: OrderedDict([('first_name', 'Ashish'), ('last_name', ''), ('email', 'ting@tong.com'), ('mobile', '9818611162'), ('business_name', 'Some business'), ('password', 'Tingtong'), ('otp', '078266')]) (2018-08-27 02:15:30; views.py:57)
ERROR:django.request: Internal Server Error: /auth/verify-otp/ (2018-08-27 02:15:53; log.py:228)
Traceback (most recent call last):
  File "/home/troll/.local/share/virtualenvs/backend-ArvMLrc1/lib/python3.6/site-packages/django/core/handlers/exception.py", line 34, in inner
    response = get_response(request)
  File "/home/troll/.local/share/virtualenvs/backend-ArvMLrc1/lib/python3.6/site-packages/django/core/handlers/base.py", line 126, in _get_response
    response = self.process_exception_by_middleware(e, request)
  File "/home/troll/.local/share/virtualenvs/backend-ArvMLrc1/lib/python3.6/site-packages/django/core/handlers/base.py", line 124, in _get_response
    response = wrapped_callback(request, *callback_args, **callback_kwargs)
  File "/home/troll/.local/share/virtualenvs/backend-ArvMLrc1/lib/python3.6/site-packages/django/views/decorators/csrf.py", line 54, in wrapped_view
    return view_func(*args, **kwargs)
  File "/home/troll/.local/share/virtualenvs/backend-ArvMLrc1/lib/python3.6/site-packages/django/views/generic/base.py", line 68, in view
    return self.dispatch(request, *args, **kwargs)
  File "/home/troll/.local/share/virtualenvs/backend-ArvMLrc1/lib/python3.6/site-packages/rest_framework/views.py", line 483, in dispatch
    response = self.handle_exception(exc)
  File "/home/troll/.local/share/virtualenvs/backend-ArvMLrc1/lib/python3.6/site-packages/rest_framework/views.py", line 443, in handle_exception
    self.raise_uncaught_exception(exc)
  File "/home/troll/.local/share/virtualenvs/backend-ArvMLrc1/lib/python3.6/site-packages/rest_framework/views.py", line 480, in dispatch
    response = handler(request, *args, **kwargs)
  File "/home/troll/procom-com/backend/procom_backend/jwt_auth/views.py", line 117, in post
    user = create_user_with_profile(validated_data)
  File "/home/troll/procom-com/backend/procom_backend/jwt_auth/utils.py", line 49, in create_user_with_profile
    gstin=validated_data['gstin'],
KeyError: 'gstin'
ERROR:django.request: Internal Server Error: /auth/verify-otp/ (2018-08-27 02:15:54; log.py:228)
Traceback (most recent call last):
  File "/home/troll/.local/share/virtualenvs/backend-ArvMLrc1/lib/python3.6/site-packages/django/db/backends/utils.py", line 85, in _execute
    return self.cursor.execute(sql, params)
psycopg2.IntegrityError: duplicate key value violates unique constraint "auth_user_username_key"
DETAIL:  Key (username)=(Adlxg7) already exists.


The above exception was the direct cause of the following exception:

Traceback (most recent call last):
  File "/home/troll/.local/share/virtualenvs/backend-ArvMLrc1/lib/python3.6/site-packages/django/core/handlers/exception.py", line 34, in inner
    response = get_response(request)
  File "/home/troll/.local/share/virtualenvs/backend-ArvMLrc1/lib/python3.6/site-packages/django/core/handlers/base.py", line 126, in _get_response
    response = self.process_exception_by_middleware(e, request)
  File "/home/troll/.local/share/virtualenvs/backend-ArvMLrc1/lib/python3.6/site-packages/django/core/handlers/base.py", line 124, in _get_response
    response = wrapped_callback(request, *callback_args, **callback_kwargs)
  File "/home/troll/.local/share/virtualenvs/backend-ArvMLrc1/lib/python3.6/site-packages/django/views/decorators/csrf.py", line 54, in wrapped_view
    return view_func(*args, **kwargs)
  File "/home/troll/.local/share/virtualenvs/backend-ArvMLrc1/lib/python3.6/site-packages/django/views/generic/base.py", line 68, in view
    return self.dispatch(request, *args, **kwargs)
  File "/home/troll/.local/share/virtualenvs/backend-ArvMLrc1/lib/python3.6/site-packages/rest_framework/views.py", line 483, in dispatch
    response = self.handle_exception(exc)
  File "/home/troll/.local/share/virtualenvs/backend-ArvMLrc1/lib/python3.6/site-packages/rest_framework/views.py", line 443, in handle_exception
    self.raise_uncaught_exception(exc)
  File "/home/troll/.local/share/virtualenvs/backend-ArvMLrc1/lib/python3.6/site-packages/rest_framework/views.py", line 480, in dispatch
    response = handler(request, *args, **kwargs)
  File "/home/troll/procom-com/backend/procom_backend/jwt_auth/views.py", line 117, in post
    user = create_user_with_profile(validated_data)
  File "/home/troll/procom-com/backend/procom_backend/jwt_auth/utils.py", line 47, in create_user_with_profile
    user.save()
  File "/home/troll/.local/share/virtualenvs/backend-ArvMLrc1/lib/python3.6/site-packages/django/contrib/auth/base_user.py", line 73, in save
    super().save(*args, **kwargs)
  File "/home/troll/.local/share/virtualenvs/backend-ArvMLrc1/lib/python3.6/site-packages/django/db/models/base.py", line 717, in save
    force_update=force_update, update_fields=update_fields)
  File "/home/troll/.local/share/virtualenvs/backend-ArvMLrc1/lib/python3.6/site-packages/django/db/models/base.py", line 747, in save_base
    updated = self._save_table(raw, cls, force_insert, force_update, using, update_fields)
  File "/home/troll/.local/share/virtualenvs/backend-ArvMLrc1/lib/python3.6/site-packages/django/db/models/base.py", line 830, in _save_table
    result = self._do_insert(cls._base_manager, using, fields, update_pk, raw)
  File "/home/troll/.local/share/virtualenvs/backend-ArvMLrc1/lib/python3.6/site-packages/django/db/models/base.py", line 868, in _do_insert
    using=using, raw=raw)
  File "/home/troll/.local/share/virtualenvs/backend-ArvMLrc1/lib/python3.6/site-packages/django/db/models/manager.py", line 82, in manager_method
    return getattr(self.get_queryset(), name)(*args, **kwargs)
  File "/home/troll/.local/share/virtualenvs/backend-ArvMLrc1/lib/python3.6/site-packages/django/db/models/query.py", line 1133, in _insert
    return query.get_compiler(using=using).execute_sql(return_id)
  File "/home/troll/.local/share/virtualenvs/backend-ArvMLrc1/lib/python3.6/site-packages/django/db/models/sql/compiler.py", line 1285, in execute_sql
    cursor.execute(sql, params)
  File "/home/troll/.local/share/virtualenvs/backend-ArvMLrc1/lib/python3.6/site-packages/django/db/backends/utils.py", line 100, in execute
    return super().execute(sql, params)
  File "/home/troll/.local/share/virtualenvs/backend-ArvMLrc1/lib/python3.6/site-packages/django/db/backends/utils.py", line 68, in execute
    return self._execute_with_wrappers(sql, params, many=False, executor=self._execute)
  File "/home/troll/.local/share/virtualenvs/backend-ArvMLrc1/lib/python3.6/site-packages/django/db/backends/utils.py", line 77, in _execute_with_wrappers
    return executor(sql, params, many, context)
  File "/home/troll/.local/share/virtualenvs/backend-ArvMLrc1/lib/python3.6/site-packages/django/db/backends/utils.py", line 85, in _execute
    return self.cursor.execute(sql, params)
  File "/home/troll/.local/share/virtualenvs/backend-ArvMLrc1/lib/python3.6/site-packages/django/db/utils.py", line 89, in __exit__
    raise dj_exc_value.with_traceback(traceback) from exc_value
  File "/home/troll/.local/share/virtualenvs/backend-ArvMLrc1/lib/python3.6/site-packages/django/db/backends/utils.py", line 85, in _execute
    return self.cursor.execute(sql, params)
django.db.utils.IntegrityError: duplicate key value violates unique constraint "auth_user_username_key"
DETAIL:  Key (username)=(Adlxg7) already exists.

ERROR:django.request: Internal Server Error: /auth/verify-otp/ (2018-08-27 02:15:54; log.py:228)
Traceback (most recent call last):
  File "/home/troll/.local/share/virtualenvs/backend-ArvMLrc1/lib/python3.6/site-packages/django/db/backends/utils.py", line 85, in _execute
    return self.cursor.execute(sql, params)
psycopg2.IntegrityError: duplicate key value violates unique constraint "auth_user_username_key"
DETAIL:  Key (username)=(Adlxg7) already exists.


The above exception was the direct cause of the following exception:

Traceback (most recent call last):
  File "/home/troll/.local/share/virtualenvs/backend-ArvMLrc1/lib/python3.6/site-packages/django/core/handlers/exception.py", line 34, in inner
    response = get_response(request)
  File "/home/troll/.local/share/virtualenvs/backend-ArvMLrc1/lib/python3.6/site-packages/django/core/handlers/base.py", line 126, in _get_response
    response = self.process_exception_by_middleware(e, request)
  File "/home/troll/.local/share/virtualenvs/backend-ArvMLrc1/lib/python3.6/site-packages/django/core/handlers/base.py", line 124, in _get_response
    response = wrapped_callback(request, *callback_args, **callback_kwargs)
  File "/home/troll/.local/share/virtualenvs/backend-ArvMLrc1/lib/python3.6/site-packages/django/views/decorators/csrf.py", line 54, in wrapped_view
    return view_func(*args, **kwargs)
  File "/home/troll/.local/share/virtualenvs/backend-ArvMLrc1/lib/python3.6/site-packages/django/views/generic/base.py", line 68, in view
    return self.dispatch(request, *args, **kwargs)
  File "/home/troll/.local/share/virtualenvs/backend-ArvMLrc1/lib/python3.6/site-packages/rest_framework/views.py", line 483, in dispatch
    response = self.handle_exception(exc)
  File "/home/troll/.local/share/virtualenvs/backend-ArvMLrc1/lib/python3.6/site-packages/rest_framework/views.py", line 443, in handle_exception
    self.raise_uncaught_exception(exc)
  File "/home/troll/.local/share/virtualenvs/backend-ArvMLrc1/lib/python3.6/site-packages/rest_framework/views.py", line 480, in dispatch
    response = handler(request, *args, **kwargs)
  File "/home/troll/procom-com/backend/procom_backend/jwt_auth/views.py", line 117, in post
    user = create_user_with_profile(validated_data)
  File "/home/troll/procom-com/backend/procom_backend/jwt_auth/utils.py", line 47, in create_user_with_profile
    user.save()
  File "/home/troll/.local/share/virtualenvs/backend-ArvMLrc1/lib/python3.6/site-packages/django/contrib/auth/base_user.py", line 73, in save
    super().save(*args, **kwargs)
  File "/home/troll/.local/share/virtualenvs/backend-ArvMLrc1/lib/python3.6/site-packages/django/db/models/base.py", line 717, in save
    force_update=force_update, update_fields=update_fields)
  File "/home/troll/.local/share/virtualenvs/backend-ArvMLrc1/lib/python3.6/site-packages/django/db/models/base.py", line 747, in save_base
    updated = self._save_table(raw, cls, force_insert, force_update, using, update_fields)
  File "/home/troll/.local/share/virtualenvs/backend-ArvMLrc1/lib/python3.6/site-packages/django/db/models/base.py", line 830, in _save_table
    result = self._do_insert(cls._base_manager, using, fields, update_pk, raw)
  File "/home/troll/.local/share/virtualenvs/backend-ArvMLrc1/lib/python3.6/site-packages/django/db/models/base.py", line 868, in _do_insert
    using=using, raw=raw)
  File "/home/troll/.local/share/virtualenvs/backend-ArvMLrc1/lib/python3.6/site-packages/django/db/models/manager.py", line 82, in manager_method
    return getattr(self.get_queryset(), name)(*args, **kwargs)
  File "/home/troll/.local/share/virtualenvs/backend-ArvMLrc1/lib/python3.6/site-packages/django/db/models/query.py", line 1133, in _insert
    return query.get_compiler(using=using).execute_sql(return_id)
  File "/home/troll/.local/share/virtualenvs/backend-ArvMLrc1/lib/python3.6/site-packages/django/db/models/sql/compiler.py", line 1285, in execute_sql
    cursor.execute(sql, params)
  File "/home/troll/.local/share/virtualenvs/backend-ArvMLrc1/lib/python3.6/site-packages/django/db/backends/utils.py", line 100, in execute
    return super().execute(sql, params)
  File "/home/troll/.local/share/virtualenvs/backend-ArvMLrc1/lib/python3.6/site-packages/django/db/backends/utils.py", line 68, in execute
    return self._execute_with_wrappers(sql, params, many=False, executor=self._execute)
  File "/home/troll/.local/share/virtualenvs/backend-ArvMLrc1/lib/python3.6/site-packages/django/db/backends/utils.py", line 77, in _execute_with_wrappers
    return executor(sql, params, many, context)
  File "/home/troll/.local/share/virtualenvs/backend-ArvMLrc1/lib/python3.6/site-packages/django/db/backends/utils.py", line 85, in _execute
    return self.cursor.execute(sql, params)
  File "/home/troll/.local/share/virtualenvs/backend-ArvMLrc1/lib/python3.6/site-packages/django/db/utils.py", line 89, in __exit__
    raise dj_exc_value.with_traceback(traceback) from exc_value
  File "/home/troll/.local/share/virtualenvs/backend-ArvMLrc1/lib/python3.6/site-packages/django/db/backends/utils.py", line 85, in _execute
    return self.cursor.execute(sql, params)
django.db.utils.IntegrityError: duplicate key value violates unique constraint "auth_user_username_key"
DETAIL:  Key (username)=(Adlxg7) already exists.

ERROR:django.request: Internal Server Error: /auth/verify-otp/ (2018-08-27 02:15:54; log.py:228)
Traceback (most recent call last):
  File "/home/troll/.local/share/virtualenvs/backend-ArvMLrc1/lib/python3.6/site-packages/django/db/backends/utils.py", line 85, in _execute
    return self.cursor.execute(sql, params)
psycopg2.IntegrityError: duplicate key value violates unique constraint "auth_user_username_key"
DETAIL:  Key (username)=(Adlxg7) already exists.


The above exception was the direct cause of the following exception:

Traceback (most recent call last):
  File "/home/troll/.local/share/virtualenvs/backend-ArvMLrc1/lib/python3.6/site-packages/django/core/handlers/exception.py", line 34, in inner
    response = get_response(request)
  File "/home/troll/.local/share/virtualenvs/backend-ArvMLrc1/lib/python3.6/site-packages/django/core/handlers/base.py", line 126, in _get_response
    response = self.process_exception_by_middleware(e, request)
  File "/home/troll/.local/share/virtualenvs/backend-ArvMLrc1/lib/python3.6/site-packages/django/core/handlers/base.py", line 124, in _get_response
    response = wrapped_callback(request, *callback_args, **callback_kwargs)
  File "/home/troll/.local/share/virtualenvs/backend-ArvMLrc1/lib/python3.6/site-packages/django/views/decorators/csrf.py", line 54, in wrapped_view
    return view_func(*args, **kwargs)
  File "/home/troll/.local/share/virtualenvs/backend-ArvMLrc1/lib/python3.6/site-packages/django/views/generic/base.py", line 68, in view
    return self.dispatch(request, *args, **kwargs)
  File "/home/troll/.local/share/virtualenvs/backend-ArvMLrc1/lib/python3.6/site-packages/rest_framework/views.py", line 483, in dispatch
    response = self.handle_exception(exc)
  File "/home/troll/.local/share/virtualenvs/backend-ArvMLrc1/lib/python3.6/site-packages/rest_framework/views.py", line 443, in handle_exception
    self.raise_uncaught_exception(exc)
  File "/home/troll/.local/share/virtualenvs/backend-ArvMLrc1/lib/python3.6/site-packages/rest_framework/views.py", line 480, in dispatch
    response = handler(request, *args, **kwargs)
  File "/home/troll/procom-com/backend/procom_backend/jwt_auth/views.py", line 117, in post
    user = create_user_with_profile(validated_data)
  File "/home/troll/procom-com/backend/procom_backend/jwt_auth/utils.py", line 47, in create_user_with_profile
    user.save()
  File "/home/troll/.local/share/virtualenvs/backend-ArvMLrc1/lib/python3.6/site-packages/django/contrib/auth/base_user.py", line 73, in save
    super().save(*args, **kwargs)
  File "/home/troll/.local/share/virtualenvs/backend-ArvMLrc1/lib/python3.6/site-packages/django/db/models/base.py", line 717, in save
    force_update=force_update, update_fields=update_fields)
  File "/home/troll/.local/share/virtualenvs/backend-ArvMLrc1/lib/python3.6/site-packages/django/db/models/base.py", line 747, in save_base
    updated = self._save_table(raw, cls, force_insert, force_update, using, update_fields)
  File "/home/troll/.local/share/virtualenvs/backend-ArvMLrc1/lib/python3.6/site-packages/django/db/models/base.py", line 830, in _save_table
    result = self._do_insert(cls._base_manager, using, fields, update_pk, raw)
  File "/home/troll/.local/share/virtualenvs/backend-ArvMLrc1/lib/python3.6/site-packages/django/db/models/base.py", line 868, in _do_insert
    using=using, raw=raw)
  File "/home/troll/.local/share/virtualenvs/backend-ArvMLrc1/lib/python3.6/site-packages/django/db/models/manager.py", line 82, in manager_method
    return getattr(self.get_queryset(), name)(*args, **kwargs)
  File "/home/troll/.local/share/virtualenvs/backend-ArvMLrc1/lib/python3.6/site-packages/django/db/models/query.py", line 1133, in _insert
    return query.get_compiler(using=using).execute_sql(return_id)
  File "/home/troll/.local/share/virtualenvs/backend-ArvMLrc1/lib/python3.6/site-packages/django/db/models/sql/compiler.py", line 1285, in execute_sql
    cursor.execute(sql, params)
  File "/home/troll/.local/share/virtualenvs/backend-ArvMLrc1/lib/python3.6/site-packages/django/db/backends/utils.py", line 100, in execute
    return super().execute(sql, params)
  File "/home/troll/.local/share/virtualenvs/backend-ArvMLrc1/lib/python3.6/site-packages/django/db/backends/utils.py", line 68, in execute
    return self._execute_with_wrappers(sql, params, many=False, executor=self._execute)
  File "/home/troll/.local/share/virtualenvs/backend-ArvMLrc1/lib/python3.6/site-packages/django/db/backends/utils.py", line 77, in _execute_with_wrappers
    return executor(sql, params, many, context)
  File "/home/troll/.local/share/virtualenvs/backend-ArvMLrc1/lib/python3.6/site-packages/django/db/backends/utils.py", line 85, in _execute
    return self.cursor.execute(sql, params)
  File "/home/troll/.local/share/virtualenvs/backend-ArvMLrc1/lib/python3.6/site-packages/django/db/utils.py", line 89, in __exit__
    raise dj_exc_value.with_traceback(traceback) from exc_value
  File "/home/troll/.local/share/virtualenvs/backend-ArvMLrc1/lib/python3.6/site-packages/django/db/backends/utils.py", line 85, in _execute
    return self.cursor.execute(sql, params)
django.db.utils.IntegrityError: duplicate key value violates unique constraint "auth_user_username_key"
DETAIL:  Key (username)=(Adlxg7) already exists.

ERROR:django.request: Internal Server Error: /auth/verify-otp/ (2018-08-27 02:17:19; log.py:228)
Traceback (most recent call last):
  File "/home/troll/.local/share/virtualenvs/backend-ArvMLrc1/lib/python3.6/site-packages/django/db/backends/utils.py", line 85, in _execute
    return self.cursor.execute(sql, params)
psycopg2.IntegrityError: duplicate key value violates unique constraint "auth_user_username_key"
DETAIL:  Key (username)=(Adlxg7) already exists.


The above exception was the direct cause of the following exception:

Traceback (most recent call last):
  File "/home/troll/.local/share/virtualenvs/backend-ArvMLrc1/lib/python3.6/site-packages/django/core/handlers/exception.py", line 34, in inner
    response = get_response(request)
  File "/home/troll/.local/share/virtualenvs/backend-ArvMLrc1/lib/python3.6/site-packages/django/core/handlers/base.py", line 126, in _get_response
    response = self.process_exception_by_middleware(e, request)
  File "/home/troll/.local/share/virtualenvs/backend-ArvMLrc1/lib/python3.6/site-packages/django/core/handlers/base.py", line 124, in _get_response
    response = wrapped_callback(request, *callback_args, **callback_kwargs)
  File "/home/troll/.local/share/virtualenvs/backend-ArvMLrc1/lib/python3.6/site-packages/django/views/decorators/csrf.py", line 54, in wrapped_view
    return view_func(*args, **kwargs)
  File "/home/troll/.local/share/virtualenvs/backend-ArvMLrc1/lib/python3.6/site-packages/django/views/generic/base.py", line 68, in view
    return self.dispatch(request, *args, **kwargs)
  File "/home/troll/.local/share/virtualenvs/backend-ArvMLrc1/lib/python3.6/site-packages/rest_framework/views.py", line 483, in dispatch
    response = self.handle_exception(exc)
  File "/home/troll/.local/share/virtualenvs/backend-ArvMLrc1/lib/python3.6/site-packages/rest_framework/views.py", line 443, in handle_exception
    self.raise_uncaught_exception(exc)
  File "/home/troll/.local/share/virtualenvs/backend-ArvMLrc1/lib/python3.6/site-packages/rest_framework/views.py", line 480, in dispatch
    response = handler(request, *args, **kwargs)
  File "/home/troll/procom-com/backend/procom_backend/jwt_auth/views.py", line 117, in post
    user = create_user_with_profile(validated_data)
  File "/home/troll/procom-com/backend/procom_backend/jwt_auth/utils.py", line 47, in create_user_with_profile
    user.save()
  File "/home/troll/.local/share/virtualenvs/backend-ArvMLrc1/lib/python3.6/site-packages/django/contrib/auth/base_user.py", line 73, in save
    super().save(*args, **kwargs)
  File "/home/troll/.local/share/virtualenvs/backend-ArvMLrc1/lib/python3.6/site-packages/django/db/models/base.py", line 717, in save
    force_update=force_update, update_fields=update_fields)
  File "/home/troll/.local/share/virtualenvs/backend-ArvMLrc1/lib/python3.6/site-packages/django/db/models/base.py", line 747, in save_base
    updated = self._save_table(raw, cls, force_insert, force_update, using, update_fields)
  File "/home/troll/.local/share/virtualenvs/backend-ArvMLrc1/lib/python3.6/site-packages/django/db/models/base.py", line 830, in _save_table
    result = self._do_insert(cls._base_manager, using, fields, update_pk, raw)
  File "/home/troll/.local/share/virtualenvs/backend-ArvMLrc1/lib/python3.6/site-packages/django/db/models/base.py", line 868, in _do_insert
    using=using, raw=raw)
  File "/home/troll/.local/share/virtualenvs/backend-ArvMLrc1/lib/python3.6/site-packages/django/db/models/manager.py", line 82, in manager_method
    return getattr(self.get_queryset(), name)(*args, **kwargs)
  File "/home/troll/.local/share/virtualenvs/backend-ArvMLrc1/lib/python3.6/site-packages/django/db/models/query.py", line 1133, in _insert
    return query.get_compiler(using=using).execute_sql(return_id)
  File "/home/troll/.local/share/virtualenvs/backend-ArvMLrc1/lib/python3.6/site-packages/django/db/models/sql/compiler.py", line 1285, in execute_sql
    cursor.execute(sql, params)
  File "/home/troll/.local/share/virtualenvs/backend-ArvMLrc1/lib/python3.6/site-packages/django/db/backends/utils.py", line 100, in execute
    return super().execute(sql, params)
  File "/home/troll/.local/share/virtualenvs/backend-ArvMLrc1/lib/python3.6/site-packages/django/db/backends/utils.py", line 68, in execute
    return self._execute_with_wrappers(sql, params, many=False, executor=self._execute)
  File "/home/troll/.local/share/virtualenvs/backend-ArvMLrc1/lib/python3.6/site-packages/django/db/backends/utils.py", line 77, in _execute_with_wrappers
    return executor(sql, params, many, context)
  File "/home/troll/.local/share/virtualenvs/backend-ArvMLrc1/lib/python3.6/site-packages/django/db/backends/utils.py", line 85, in _execute
    return self.cursor.execute(sql, params)
  File "/home/troll/.local/share/virtualenvs/backend-ArvMLrc1/lib/python3.6/site-packages/django/db/utils.py", line 89, in __exit__
    raise dj_exc_value.with_traceback(traceback) from exc_value
  File "/home/troll/.local/share/virtualenvs/backend-ArvMLrc1/lib/python3.6/site-packages/django/db/backends/utils.py", line 85, in _execute
    return self.cursor.execute(sql, params)
django.db.utils.IntegrityError: duplicate key value violates unique constraint "auth_user_username_key"
DETAIL:  Key (username)=(Adlxg7) already exists.

ERROR:django.request: Internal Server Error: /auth/verify-otp/ (2018-08-27 02:17:19; log.py:228)
Traceback (most recent call last):
  File "/home/troll/.local/share/virtualenvs/backend-ArvMLrc1/lib/python3.6/site-packages/django/db/backends/utils.py", line 85, in _execute
    return self.cursor.execute(sql, params)
psycopg2.IntegrityError: duplicate key value violates unique constraint "auth_user_username_key"
DETAIL:  Key (username)=(Adlxg7) already exists.


The above exception was the direct cause of the following exception:

Traceback (most recent call last):
  File "/home/troll/.local/share/virtualenvs/backend-ArvMLrc1/lib/python3.6/site-packages/django/core/handlers/exception.py", line 34, in inner
    response = get_response(request)
  File "/home/troll/.local/share/virtualenvs/backend-ArvMLrc1/lib/python3.6/site-packages/django/core/handlers/base.py", line 126, in _get_response
    response = self.process_exception_by_middleware(e, request)
  File "/home/troll/.local/share/virtualenvs/backend-ArvMLrc1/lib/python3.6/site-packages/django/core/handlers/base.py", line 124, in _get_response
    response = wrapped_callback(request, *callback_args, **callback_kwargs)
  File "/home/troll/.local/share/virtualenvs/backend-ArvMLrc1/lib/python3.6/site-packages/django/views/decorators/csrf.py", line 54, in wrapped_view
    return view_func(*args, **kwargs)
  File "/home/troll/.local/share/virtualenvs/backend-ArvMLrc1/lib/python3.6/site-packages/django/views/generic/base.py", line 68, in view
    return self.dispatch(request, *args, **kwargs)
  File "/home/troll/.local/share/virtualenvs/backend-ArvMLrc1/lib/python3.6/site-packages/rest_framework/views.py", line 483, in dispatch
    response = self.handle_exception(exc)
  File "/home/troll/.local/share/virtualenvs/backend-ArvMLrc1/lib/python3.6/site-packages/rest_framework/views.py", line 443, in handle_exception
    self.raise_uncaught_exception(exc)
  File "/home/troll/.local/share/virtualenvs/backend-ArvMLrc1/lib/python3.6/site-packages/rest_framework/views.py", line 480, in dispatch
    response = handler(request, *args, **kwargs)
  File "/home/troll/procom-com/backend/procom_backend/jwt_auth/views.py", line 117, in post
    user = create_user_with_profile(validated_data)
  File "/home/troll/procom-com/backend/procom_backend/jwt_auth/utils.py", line 47, in create_user_with_profile
    user.save()
  File "/home/troll/.local/share/virtualenvs/backend-ArvMLrc1/lib/python3.6/site-packages/django/contrib/auth/base_user.py", line 73, in save
    super().save(*args, **kwargs)
  File "/home/troll/.local/share/virtualenvs/backend-ArvMLrc1/lib/python3.6/site-packages/django/db/models/base.py", line 717, in save
    force_update=force_update, update_fields=update_fields)
  File "/home/troll/.local/share/virtualenvs/backend-ArvMLrc1/lib/python3.6/site-packages/django/db/models/base.py", line 747, in save_base
    updated = self._save_table(raw, cls, force_insert, force_update, using, update_fields)
  File "/home/troll/.local/share/virtualenvs/backend-ArvMLrc1/lib/python3.6/site-packages/django/db/models/base.py", line 830, in _save_table
    result = self._do_insert(cls._base_manager, using, fields, update_pk, raw)
  File "/home/troll/.local/share/virtualenvs/backend-ArvMLrc1/lib/python3.6/site-packages/django/db/models/base.py", line 868, in _do_insert
    using=using, raw=raw)
  File "/home/troll/.local/share/virtualenvs/backend-ArvMLrc1/lib/python3.6/site-packages/django/db/models/manager.py", line 82, in manager_method
    return getattr(self.get_queryset(), name)(*args, **kwargs)
  File "/home/troll/.local/share/virtualenvs/backend-ArvMLrc1/lib/python3.6/site-packages/django/db/models/query.py", line 1133, in _insert
    return query.get_compiler(using=using).execute_sql(return_id)
  File "/home/troll/.local/share/virtualenvs/backend-ArvMLrc1/lib/python3.6/site-packages/django/db/models/sql/compiler.py", line 1285, in execute_sql
    cursor.execute(sql, params)
  File "/home/troll/.local/share/virtualenvs/backend-ArvMLrc1/lib/python3.6/site-packages/django/db/backends/utils.py", line 100, in execute
    return super().execute(sql, params)
  File "/home/troll/.local/share/virtualenvs/backend-ArvMLrc1/lib/python3.6/site-packages/django/db/backends/utils.py", line 68, in execute
    return self._execute_with_wrappers(sql, params, many=False, executor=self._execute)
  File "/home/troll/.local/share/virtualenvs/backend-ArvMLrc1/lib/python3.6/site-packages/django/db/backends/utils.py", line 77, in _execute_with_wrappers
    return executor(sql, params, many, context)
  File "/home/troll/.local/share/virtualenvs/backend-ArvMLrc1/lib/python3.6/site-packages/django/db/backends/utils.py", line 85, in _execute
    return self.cursor.execute(sql, params)
  File "/home/troll/.local/share/virtualenvs/backend-ArvMLrc1/lib/python3.6/site-packages/django/db/utils.py", line 89, in __exit__
    raise dj_exc_value.with_traceback(traceback) from exc_value
  File "/home/troll/.local/share/virtualenvs/backend-ArvMLrc1/lib/python3.6/site-packages/django/db/backends/utils.py", line 85, in _execute
    return self.cursor.execute(sql, params)
django.db.utils.IntegrityError: duplicate key value violates unique constraint "auth_user_username_key"
DETAIL:  Key (username)=(Adlxg7) already exists.

ERROR:django.request: Internal Server Error: /auth/verify-otp/ (2018-08-27 02:17:19; log.py:228)
Traceback (most recent call last):
  File "/home/troll/.local/share/virtualenvs/backend-ArvMLrc1/lib/python3.6/site-packages/django/db/backends/utils.py", line 85, in _execute
    return self.cursor.execute(sql, params)
psycopg2.IntegrityError: duplicate key value violates unique constraint "auth_user_username_key"
DETAIL:  Key (username)=(Adlxg7) already exists.


The above exception was the direct cause of the following exception:

Traceback (most recent call last):
  File "/home/troll/.local/share/virtualenvs/backend-ArvMLrc1/lib/python3.6/site-packages/django/core/handlers/exception.py", line 34, in inner
    response = get_response(request)
  File "/home/troll/.local/share/virtualenvs/backend-ArvMLrc1/lib/python3.6/site-packages/django/core/handlers/base.py", line 126, in _get_response
    response = self.process_exception_by_middleware(e, request)
  File "/home/troll/.local/share/virtualenvs/backend-ArvMLrc1/lib/python3.6/site-packages/django/core/handlers/base.py", line 124, in _get_response
    response = wrapped_callback(request, *callback_args, **callback_kwargs)
  File "/home/troll/.local/share/virtualenvs/backend-ArvMLrc1/lib/python3.6/site-packages/django/views/decorators/csrf.py", line 54, in wrapped_view
    return view_func(*args, **kwargs)
  File "/home/troll/.local/share/virtualenvs/backend-ArvMLrc1/lib/python3.6/site-packages/django/views/generic/base.py", line 68, in view
    return self.dispatch(request, *args, **kwargs)
  File "/home/troll/.local/share/virtualenvs/backend-ArvMLrc1/lib/python3.6/site-packages/rest_framework/views.py", line 483, in dispatch
    response = self.handle_exception(exc)
  File "/home/troll/.local/share/virtualenvs/backend-ArvMLrc1/lib/python3.6/site-packages/rest_framework/views.py", line 443, in handle_exception
    self.raise_uncaught_exception(exc)
  File "/home/troll/.local/share/virtualenvs/backend-ArvMLrc1/lib/python3.6/site-packages/rest_framework/views.py", line 480, in dispatch
    response = handler(request, *args, **kwargs)
  File "/home/troll/procom-com/backend/procom_backend/jwt_auth/views.py", line 117, in post
    user = create_user_with_profile(validated_data)
  File "/home/troll/procom-com/backend/procom_backend/jwt_auth/utils.py", line 47, in create_user_with_profile
    user.save()
  File "/home/troll/.local/share/virtualenvs/backend-ArvMLrc1/lib/python3.6/site-packages/django/contrib/auth/base_user.py", line 73, in save
    super().save(*args, **kwargs)
  File "/home/troll/.local/share/virtualenvs/backend-ArvMLrc1/lib/python3.6/site-packages/django/db/models/base.py", line 717, in save
    force_update=force_update, update_fields=update_fields)
  File "/home/troll/.local/share/virtualenvs/backend-ArvMLrc1/lib/python3.6/site-packages/django/db/models/base.py", line 747, in save_base
    updated = self._save_table(raw, cls, force_insert, force_update, using, update_fields)
  File "/home/troll/.local/share/virtualenvs/backend-ArvMLrc1/lib/python3.6/site-packages/django/db/models/base.py", line 830, in _save_table
    result = self._do_insert(cls._base_manager, using, fields, update_pk, raw)
  File "/home/troll/.local/share/virtualenvs/backend-ArvMLrc1/lib/python3.6/site-packages/django/db/models/base.py", line 868, in _do_insert
    using=using, raw=raw)
  File "/home/troll/.local/share/virtualenvs/backend-ArvMLrc1/lib/python3.6/site-packages/django/db/models/manager.py", line 82, in manager_method
    return getattr(self.get_queryset(), name)(*args, **kwargs)
  File "/home/troll/.local/share/virtualenvs/backend-ArvMLrc1/lib/python3.6/site-packages/django/db/models/query.py", line 1133, in _insert
    return query.get_compiler(using=using).execute_sql(return_id)
  File "/home/troll/.local/share/virtualenvs/backend-ArvMLrc1/lib/python3.6/site-packages/django/db/models/sql/compiler.py", line 1285, in execute_sql
    cursor.execute(sql, params)
  File "/home/troll/.local/share/virtualenvs/backend-ArvMLrc1/lib/python3.6/site-packages/django/db/backends/utils.py", line 100, in execute
    return super().execute(sql, params)
  File "/home/troll/.local/share/virtualenvs/backend-ArvMLrc1/lib/python3.6/site-packages/django/db/backends/utils.py", line 68, in execute
    return self._execute_with_wrappers(sql, params, many=False, executor=self._execute)
  File "/home/troll/.local/share/virtualenvs/backend-ArvMLrc1/lib/python3.6/site-packages/django/db/backends/utils.py", line 77, in _execute_with_wrappers
    return executor(sql, params, many, context)
  File "/home/troll/.local/share/virtualenvs/backend-ArvMLrc1/lib/python3.6/site-packages/django/db/backends/utils.py", line 85, in _execute
    return self.cursor.execute(sql, params)
  File "/home/troll/.local/share/virtualenvs/backend-ArvMLrc1/lib/python3.6/site-packages/django/db/utils.py", line 89, in __exit__
    raise dj_exc_value.with_traceback(traceback) from exc_value
  File "/home/troll/.local/share/virtualenvs/backend-ArvMLrc1/lib/python3.6/site-packages/django/db/backends/utils.py", line 85, in _execute
    return self.cursor.execute(sql, params)
django.db.utils.IntegrityError: duplicate key value violates unique constraint "auth_user_username_key"
DETAIL:  Key (username)=(Adlxg7) already exists.

ERROR:django.request: Internal Server Error: /auth/verify-otp/ (2018-08-27 02:17:19; log.py:228)
Traceback (most recent call last):
  File "/home/troll/.local/share/virtualenvs/backend-ArvMLrc1/lib/python3.6/site-packages/django/db/backends/utils.py", line 85, in _execute
    return self.cursor.execute(sql, params)
psycopg2.IntegrityError: duplicate key value violates unique constraint "auth_user_username_key"
DETAIL:  Key (username)=(Adlxg7) already exists.


The above exception was the direct cause of the following exception:

Traceback (most recent call last):
  File "/home/troll/.local/share/virtualenvs/backend-ArvMLrc1/lib/python3.6/site-packages/django/core/handlers/exception.py", line 34, in inner
    response = get_response(request)
  File "/home/troll/.local/share/virtualenvs/backend-ArvMLrc1/lib/python3.6/site-packages/django/core/handlers/base.py", line 126, in _get_response
    response = self.process_exception_by_middleware(e, request)
  File "/home/troll/.local/share/virtualenvs/backend-ArvMLrc1/lib/python3.6/site-packages/django/core/handlers/base.py", line 124, in _get_response
    response = wrapped_callback(request, *callback_args, **callback_kwargs)
  File "/home/troll/.local/share/virtualenvs/backend-ArvMLrc1/lib/python3.6/site-packages/django/views/decorators/csrf.py", line 54, in wrapped_view
    return view_func(*args, **kwargs)
  File "/home/troll/.local/share/virtualenvs/backend-ArvMLrc1/lib/python3.6/site-packages/django/views/generic/base.py", line 68, in view
    return self.dispatch(request, *args, **kwargs)
  File "/home/troll/.local/share/virtualenvs/backend-ArvMLrc1/lib/python3.6/site-packages/rest_framework/views.py", line 483, in dispatch
    response = self.handle_exception(exc)
  File "/home/troll/.local/share/virtualenvs/backend-ArvMLrc1/lib/python3.6/site-packages/rest_framework/views.py", line 443, in handle_exception
    self.raise_uncaught_exception(exc)
  File "/home/troll/.local/share/virtualenvs/backend-ArvMLrc1/lib/python3.6/site-packages/rest_framework/views.py", line 480, in dispatch
    response = handler(request, *args, **kwargs)
  File "/home/troll/procom-com/backend/procom_backend/jwt_auth/views.py", line 117, in post
    user = create_user_with_profile(validated_data)
  File "/home/troll/procom-com/backend/procom_backend/jwt_auth/utils.py", line 47, in create_user_with_profile
    user.save()
  File "/home/troll/.local/share/virtualenvs/backend-ArvMLrc1/lib/python3.6/site-packages/django/contrib/auth/base_user.py", line 73, in save
    super().save(*args, **kwargs)
  File "/home/troll/.local/share/virtualenvs/backend-ArvMLrc1/lib/python3.6/site-packages/django/db/models/base.py", line 717, in save
    force_update=force_update, update_fields=update_fields)
  File "/home/troll/.local/share/virtualenvs/backend-ArvMLrc1/lib/python3.6/site-packages/django/db/models/base.py", line 747, in save_base
    updated = self._save_table(raw, cls, force_insert, force_update, using, update_fields)
  File "/home/troll/.local/share/virtualenvs/backend-ArvMLrc1/lib/python3.6/site-packages/django/db/models/base.py", line 830, in _save_table
    result = self._do_insert(cls._base_manager, using, fields, update_pk, raw)
  File "/home/troll/.local/share/virtualenvs/backend-ArvMLrc1/lib/python3.6/site-packages/django/db/models/base.py", line 868, in _do_insert
    using=using, raw=raw)
  File "/home/troll/.local/share/virtualenvs/backend-ArvMLrc1/lib/python3.6/site-packages/django/db/models/manager.py", line 82, in manager_method
    return getattr(self.get_queryset(), name)(*args, **kwargs)
  File "/home/troll/.local/share/virtualenvs/backend-ArvMLrc1/lib/python3.6/site-packages/django/db/models/query.py", line 1133, in _insert
    return query.get_compiler(using=using).execute_sql(return_id)
  File "/home/troll/.local/share/virtualenvs/backend-ArvMLrc1/lib/python3.6/site-packages/django/db/models/sql/compiler.py", line 1285, in execute_sql
    cursor.execute(sql, params)
  File "/home/troll/.local/share/virtualenvs/backend-ArvMLrc1/lib/python3.6/site-packages/django/db/backends/utils.py", line 100, in execute
    return super().execute(sql, params)
  File "/home/troll/.local/share/virtualenvs/backend-ArvMLrc1/lib/python3.6/site-packages/django/db/backends/utils.py", line 68, in execute
    return self._execute_with_wrappers(sql, params, many=False, executor=self._execute)
  File "/home/troll/.local/share/virtualenvs/backend-ArvMLrc1/lib/python3.6/site-packages/django/db/backends/utils.py", line 77, in _execute_with_wrappers
    return executor(sql, params, many, context)
  File "/home/troll/.local/share/virtualenvs/backend-ArvMLrc1/lib/python3.6/site-packages/django/db/backends/utils.py", line 85, in _execute
    return self.cursor.execute(sql, params)
  File "/home/troll/.local/share/virtualenvs/backend-ArvMLrc1/lib/python3.6/site-packages/django/db/utils.py", line 89, in __exit__
    raise dj_exc_value.with_traceback(traceback) from exc_value
  File "/home/troll/.local/share/virtualenvs/backend-ArvMLrc1/lib/python3.6/site-packages/django/db/backends/utils.py", line 85, in _execute
    return self.cursor.execute(sql, params)
django.db.utils.IntegrityError: duplicate key value violates unique constraint "auth_user_username_key"
DETAIL:  Key (username)=(Adlxg7) already exists.

DEBUG:asyncio: Using selector: EpollSelector (2018-08-27 02:18:00; selector_events.py:65)
INFO:daphne.server: HTTP/2 support enabled (2018-08-27 02:18:01; server.py:103)
INFO:daphne.server: Configuring endpoint tcp:port=8000:interface=0.0.0.0 (2018-08-27 02:18:01; server.py:112)
INFO:daphne.server: Listening on TCP address 0.0.0.0:8000 (2018-08-27 02:18:01; server.py:143)
DEBUG:asyncio: Using selector: EpollSelector (2018-08-27 02:19:16; selector_events.py:65)
INFO:daphne.server: HTTP/2 support enabled (2018-08-27 02:19:17; server.py:103)
INFO:daphne.server: Configuring endpoint tcp:port=8000:interface=0.0.0.0 (2018-08-27 02:19:17; server.py:112)
INFO:daphne.server: Listening on TCP address 0.0.0.0:8000 (2018-08-27 02:19:17; server.py:143)
DEBUG:asyncio: Using selector: EpollSelector (2018-08-27 02:19:24; selector_events.py:65)
INFO:daphne.server: HTTP/2 support enabled (2018-08-27 02:19:24; server.py:103)
INFO:daphne.server: Configuring endpoint tcp:port=8000:interface=0.0.0.0 (2018-08-27 02:19:24; server.py:112)
INFO:daphne.server: Listening on TCP address 0.0.0.0:8000 (2018-08-27 02:19:24; server.py:143)
ERROR:django.request: Internal Server Error: /auth/verify-otp/ (2018-08-27 02:19:28; log.py:228)
Traceback (most recent call last):
  File "/home/troll/.local/share/virtualenvs/backend-ArvMLrc1/lib/python3.6/site-packages/django/db/backends/utils.py", line 85, in _execute
    return self.cursor.execute(sql, params)
psycopg2.IntegrityError: duplicate key value violates unique constraint "auth_user_username_key"
DETAIL:  Key (username)=(Adlxg7) already exists.


The above exception was the direct cause of the following exception:

Traceback (most recent call last):
  File "/home/troll/.local/share/virtualenvs/backend-ArvMLrc1/lib/python3.6/site-packages/django/core/handlers/exception.py", line 34, in inner
    response = get_response(request)
  File "/home/troll/.local/share/virtualenvs/backend-ArvMLrc1/lib/python3.6/site-packages/django/core/handlers/base.py", line 126, in _get_response
    response = self.process_exception_by_middleware(e, request)
  File "/home/troll/.local/share/virtualenvs/backend-ArvMLrc1/lib/python3.6/site-packages/django/core/handlers/base.py", line 124, in _get_response
    response = wrapped_callback(request, *callback_args, **callback_kwargs)
  File "/home/troll/.local/share/virtualenvs/backend-ArvMLrc1/lib/python3.6/site-packages/django/views/decorators/csrf.py", line 54, in wrapped_view
    return view_func(*args, **kwargs)
  File "/home/troll/.local/share/virtualenvs/backend-ArvMLrc1/lib/python3.6/site-packages/django/views/generic/base.py", line 68, in view
    return self.dispatch(request, *args, **kwargs)
  File "/home/troll/.local/share/virtualenvs/backend-ArvMLrc1/lib/python3.6/site-packages/rest_framework/views.py", line 483, in dispatch
    response = self.handle_exception(exc)
  File "/home/troll/.local/share/virtualenvs/backend-ArvMLrc1/lib/python3.6/site-packages/rest_framework/views.py", line 443, in handle_exception
    self.raise_uncaught_exception(exc)
  File "/home/troll/.local/share/virtualenvs/backend-ArvMLrc1/lib/python3.6/site-packages/rest_framework/views.py", line 480, in dispatch
    response = handler(request, *args, **kwargs)
  File "/home/troll/procom-com/backend/procom_backend/jwt_auth/views.py", line 117, in post
    user = create_user_with_profile(validated_data)
  File "/home/troll/procom-com/backend/procom_backend/jwt_auth/utils.py", line 47, in create_user_with_profile
    user.save()
  File "/home/troll/.local/share/virtualenvs/backend-ArvMLrc1/lib/python3.6/site-packages/django/contrib/auth/base_user.py", line 73, in save
    super().save(*args, **kwargs)
  File "/home/troll/.local/share/virtualenvs/backend-ArvMLrc1/lib/python3.6/site-packages/django/db/models/base.py", line 717, in save
    force_update=force_update, update_fields=update_fields)
  File "/home/troll/.local/share/virtualenvs/backend-ArvMLrc1/lib/python3.6/site-packages/django/db/models/base.py", line 747, in save_base
    updated = self._save_table(raw, cls, force_insert, force_update, using, update_fields)
  File "/home/troll/.local/share/virtualenvs/backend-ArvMLrc1/lib/python3.6/site-packages/django/db/models/base.py", line 830, in _save_table
    result = self._do_insert(cls._base_manager, using, fields, update_pk, raw)
  File "/home/troll/.local/share/virtualenvs/backend-ArvMLrc1/lib/python3.6/site-packages/django/db/models/base.py", line 868, in _do_insert
    using=using, raw=raw)
  File "/home/troll/.local/share/virtualenvs/backend-ArvMLrc1/lib/python3.6/site-packages/django/db/models/manager.py", line 82, in manager_method
    return getattr(self.get_queryset(), name)(*args, **kwargs)
  File "/home/troll/.local/share/virtualenvs/backend-ArvMLrc1/lib/python3.6/site-packages/django/db/models/query.py", line 1133, in _insert
    return query.get_compiler(using=using).execute_sql(return_id)
  File "/home/troll/.local/share/virtualenvs/backend-ArvMLrc1/lib/python3.6/site-packages/django/db/models/sql/compiler.py", line 1285, in execute_sql
    cursor.execute(sql, params)
  File "/home/troll/.local/share/virtualenvs/backend-ArvMLrc1/lib/python3.6/site-packages/django/db/backends/utils.py", line 100, in execute
    return super().execute(sql, params)
  File "/home/troll/.local/share/virtualenvs/backend-ArvMLrc1/lib/python3.6/site-packages/django/db/backends/utils.py", line 68, in execute
    return self._execute_with_wrappers(sql, params, many=False, executor=self._execute)
  File "/home/troll/.local/share/virtualenvs/backend-ArvMLrc1/lib/python3.6/site-packages/django/db/backends/utils.py", line 77, in _execute_with_wrappers
    return executor(sql, params, many, context)
  File "/home/troll/.local/share/virtualenvs/backend-ArvMLrc1/lib/python3.6/site-packages/django/db/backends/utils.py", line 85, in _execute
    return self.cursor.execute(sql, params)
  File "/home/troll/.local/share/virtualenvs/backend-ArvMLrc1/lib/python3.6/site-packages/django/db/utils.py", line 89, in __exit__
    raise dj_exc_value.with_traceback(traceback) from exc_value
  File "/home/troll/.local/share/virtualenvs/backend-ArvMLrc1/lib/python3.6/site-packages/django/db/backends/utils.py", line 85, in _execute
    return self.cursor.execute(sql, params)
django.db.utils.IntegrityError: duplicate key value violates unique constraint "auth_user_username_key"
DETAIL:  Key (username)=(Adlxg7) already exists.

ERROR:django.request: Internal Server Error: /auth/verify-otp/ (2018-08-27 02:19:28; log.py:228)
Traceback (most recent call last):
  File "/home/troll/.local/share/virtualenvs/backend-ArvMLrc1/lib/python3.6/site-packages/django/db/backends/utils.py", line 85, in _execute
    return self.cursor.execute(sql, params)
psycopg2.IntegrityError: duplicate key value violates unique constraint "auth_user_username_key"
DETAIL:  Key (username)=(Adlxg7) already exists.


The above exception was the direct cause of the following exception:

Traceback (most recent call last):
  File "/home/troll/.local/share/virtualenvs/backend-ArvMLrc1/lib/python3.6/site-packages/django/core/handlers/exception.py", line 34, in inner
    response = get_response(request)
  File "/home/troll/.local/share/virtualenvs/backend-ArvMLrc1/lib/python3.6/site-packages/django/core/handlers/base.py", line 126, in _get_response
    response = self.process_exception_by_middleware(e, request)
  File "/home/troll/.local/share/virtualenvs/backend-ArvMLrc1/lib/python3.6/site-packages/django/core/handlers/base.py", line 124, in _get_response
    response = wrapped_callback(request, *callback_args, **callback_kwargs)
  File "/home/troll/.local/share/virtualenvs/backend-ArvMLrc1/lib/python3.6/site-packages/django/views/decorators/csrf.py", line 54, in wrapped_view
    return view_func(*args, **kwargs)
  File "/home/troll/.local/share/virtualenvs/backend-ArvMLrc1/lib/python3.6/site-packages/django/views/generic/base.py", line 68, in view
    return self.dispatch(request, *args, **kwargs)
  File "/home/troll/.local/share/virtualenvs/backend-ArvMLrc1/lib/python3.6/site-packages/rest_framework/views.py", line 483, in dispatch
    response = self.handle_exception(exc)
  File "/home/troll/.local/share/virtualenvs/backend-ArvMLrc1/lib/python3.6/site-packages/rest_framework/views.py", line 443, in handle_exception
    self.raise_uncaught_exception(exc)
  File "/home/troll/.local/share/virtualenvs/backend-ArvMLrc1/lib/python3.6/site-packages/rest_framework/views.py", line 480, in dispatch
    response = handler(request, *args, **kwargs)
  File "/home/troll/procom-com/backend/procom_backend/jwt_auth/views.py", line 117, in post
    user = create_user_with_profile(validated_data)
  File "/home/troll/procom-com/backend/procom_backend/jwt_auth/utils.py", line 47, in create_user_with_profile
    user.save()
  File "/home/troll/.local/share/virtualenvs/backend-ArvMLrc1/lib/python3.6/site-packages/django/contrib/auth/base_user.py", line 73, in save
    super().save(*args, **kwargs)
  File "/home/troll/.local/share/virtualenvs/backend-ArvMLrc1/lib/python3.6/site-packages/django/db/models/base.py", line 717, in save
    force_update=force_update, update_fields=update_fields)
  File "/home/troll/.local/share/virtualenvs/backend-ArvMLrc1/lib/python3.6/site-packages/django/db/models/base.py", line 747, in save_base
    updated = self._save_table(raw, cls, force_insert, force_update, using, update_fields)
  File "/home/troll/.local/share/virtualenvs/backend-ArvMLrc1/lib/python3.6/site-packages/django/db/models/base.py", line 830, in _save_table
    result = self._do_insert(cls._base_manager, using, fields, update_pk, raw)
  File "/home/troll/.local/share/virtualenvs/backend-ArvMLrc1/lib/python3.6/site-packages/django/db/models/base.py", line 868, in _do_insert
    using=using, raw=raw)
  File "/home/troll/.local/share/virtualenvs/backend-ArvMLrc1/lib/python3.6/site-packages/django/db/models/manager.py", line 82, in manager_method
    return getattr(self.get_queryset(), name)(*args, **kwargs)
  File "/home/troll/.local/share/virtualenvs/backend-ArvMLrc1/lib/python3.6/site-packages/django/db/models/query.py", line 1133, in _insert
    return query.get_compiler(using=using).execute_sql(return_id)
  File "/home/troll/.local/share/virtualenvs/backend-ArvMLrc1/lib/python3.6/site-packages/django/db/models/sql/compiler.py", line 1285, in execute_sql
    cursor.execute(sql, params)
  File "/home/troll/.local/share/virtualenvs/backend-ArvMLrc1/lib/python3.6/site-packages/django/db/backends/utils.py", line 100, in execute
    return super().execute(sql, params)
  File "/home/troll/.local/share/virtualenvs/backend-ArvMLrc1/lib/python3.6/site-packages/django/db/backends/utils.py", line 68, in execute
    return self._execute_with_wrappers(sql, params, many=False, executor=self._execute)
  File "/home/troll/.local/share/virtualenvs/backend-ArvMLrc1/lib/python3.6/site-packages/django/db/backends/utils.py", line 77, in _execute_with_wrappers
    return executor(sql, params, many, context)
  File "/home/troll/.local/share/virtualenvs/backend-ArvMLrc1/lib/python3.6/site-packages/django/db/backends/utils.py", line 85, in _execute
    return self.cursor.execute(sql, params)
  File "/home/troll/.local/share/virtualenvs/backend-ArvMLrc1/lib/python3.6/site-packages/django/db/utils.py", line 89, in __exit__
    raise dj_exc_value.with_traceback(traceback) from exc_value
  File "/home/troll/.local/share/virtualenvs/backend-ArvMLrc1/lib/python3.6/site-packages/django/db/backends/utils.py", line 85, in _execute
    return self.cursor.execute(sql, params)
django.db.utils.IntegrityError: duplicate key value violates unique constraint "auth_user_username_key"
DETAIL:  Key (username)=(Adlxg7) already exists.

ERROR:django.request: Internal Server Error: /auth/verify-otp/ (2018-08-27 02:19:28; log.py:228)
Traceback (most recent call last):
  File "/home/troll/.local/share/virtualenvs/backend-ArvMLrc1/lib/python3.6/site-packages/django/db/backends/utils.py", line 85, in _execute
    return self.cursor.execute(sql, params)
psycopg2.IntegrityError: duplicate key value violates unique constraint "auth_user_username_key"
DETAIL:  Key (username)=(Adlxg7) already exists.


The above exception was the direct cause of the following exception:

Traceback (most recent call last):
  File "/home/troll/.local/share/virtualenvs/backend-ArvMLrc1/lib/python3.6/site-packages/django/core/handlers/exception.py", line 34, in inner
    response = get_response(request)
  File "/home/troll/.local/share/virtualenvs/backend-ArvMLrc1/lib/python3.6/site-packages/django/core/handlers/base.py", line 126, in _get_response
    response = self.process_exception_by_middleware(e, request)
  File "/home/troll/.local/share/virtualenvs/backend-ArvMLrc1/lib/python3.6/site-packages/django/core/handlers/base.py", line 124, in _get_response
    response = wrapped_callback(request, *callback_args, **callback_kwargs)
  File "/home/troll/.local/share/virtualenvs/backend-ArvMLrc1/lib/python3.6/site-packages/django/views/decorators/csrf.py", line 54, in wrapped_view
    return view_func(*args, **kwargs)
  File "/home/troll/.local/share/virtualenvs/backend-ArvMLrc1/lib/python3.6/site-packages/django/views/generic/base.py", line 68, in view
    return self.dispatch(request, *args, **kwargs)
  File "/home/troll/.local/share/virtualenvs/backend-ArvMLrc1/lib/python3.6/site-packages/rest_framework/views.py", line 483, in dispatch
    response = self.handle_exception(exc)
  File "/home/troll/.local/share/virtualenvs/backend-ArvMLrc1/lib/python3.6/site-packages/rest_framework/views.py", line 443, in handle_exception
    self.raise_uncaught_exception(exc)
  File "/home/troll/.local/share/virtualenvs/backend-ArvMLrc1/lib/python3.6/site-packages/rest_framework/views.py", line 480, in dispatch
    response = handler(request, *args, **kwargs)
  File "/home/troll/procom-com/backend/procom_backend/jwt_auth/views.py", line 117, in post
    user = create_user_with_profile(validated_data)
  File "/home/troll/procom-com/backend/procom_backend/jwt_auth/utils.py", line 47, in create_user_with_profile
    user.save()
  File "/home/troll/.local/share/virtualenvs/backend-ArvMLrc1/lib/python3.6/site-packages/django/contrib/auth/base_user.py", line 73, in save
    super().save(*args, **kwargs)
  File "/home/troll/.local/share/virtualenvs/backend-ArvMLrc1/lib/python3.6/site-packages/django/db/models/base.py", line 717, in save
    force_update=force_update, update_fields=update_fields)
  File "/home/troll/.local/share/virtualenvs/backend-ArvMLrc1/lib/python3.6/site-packages/django/db/models/base.py", line 747, in save_base
    updated = self._save_table(raw, cls, force_insert, force_update, using, update_fields)
  File "/home/troll/.local/share/virtualenvs/backend-ArvMLrc1/lib/python3.6/site-packages/django/db/models/base.py", line 830, in _save_table
    result = self._do_insert(cls._base_manager, using, fields, update_pk, raw)
  File "/home/troll/.local/share/virtualenvs/backend-ArvMLrc1/lib/python3.6/site-packages/django/db/models/base.py", line 868, in _do_insert
    using=using, raw=raw)
  File "/home/troll/.local/share/virtualenvs/backend-ArvMLrc1/lib/python3.6/site-packages/django/db/models/manager.py", line 82, in manager_method
    return getattr(self.get_queryset(), name)(*args, **kwargs)
  File "/home/troll/.local/share/virtualenvs/backend-ArvMLrc1/lib/python3.6/site-packages/django/db/models/query.py", line 1133, in _insert
    return query.get_compiler(using=using).execute_sql(return_id)
  File "/home/troll/.local/share/virtualenvs/backend-ArvMLrc1/lib/python3.6/site-packages/django/db/models/sql/compiler.py", line 1285, in execute_sql
    cursor.execute(sql, params)
  File "/home/troll/.local/share/virtualenvs/backend-ArvMLrc1/lib/python3.6/site-packages/django/db/backends/utils.py", line 100, in execute
    return super().execute(sql, params)
  File "/home/troll/.local/share/virtualenvs/backend-ArvMLrc1/lib/python3.6/site-packages/django/db/backends/utils.py", line 68, in execute
    return self._execute_with_wrappers(sql, params, many=False, executor=self._execute)
  File "/home/troll/.local/share/virtualenvs/backend-ArvMLrc1/lib/python3.6/site-packages/django/db/backends/utils.py", line 77, in _execute_with_wrappers
    return executor(sql, params, many, context)
  File "/home/troll/.local/share/virtualenvs/backend-ArvMLrc1/lib/python3.6/site-packages/django/db/backends/utils.py", line 85, in _execute
    return self.cursor.execute(sql, params)
  File "/home/troll/.local/share/virtualenvs/backend-ArvMLrc1/lib/python3.6/site-packages/django/db/utils.py", line 89, in __exit__
    raise dj_exc_value.with_traceback(traceback) from exc_value
  File "/home/troll/.local/share/virtualenvs/backend-ArvMLrc1/lib/python3.6/site-packages/django/db/backends/utils.py", line 85, in _execute
    return self.cursor.execute(sql, params)
django.db.utils.IntegrityError: duplicate key value violates unique constraint "auth_user_username_key"
DETAIL:  Key (username)=(Adlxg7) already exists.

ERROR:django.request: Internal Server Error: /auth/verify-otp/ (2018-08-27 02:19:28; log.py:228)
Traceback (most recent call last):
  File "/home/troll/.local/share/virtualenvs/backend-ArvMLrc1/lib/python3.6/site-packages/django/db/backends/utils.py", line 85, in _execute
    return self.cursor.execute(sql, params)
psycopg2.IntegrityError: duplicate key value violates unique constraint "auth_user_username_key"
DETAIL:  Key (username)=(Adlxg7) already exists.


The above exception was the direct cause of the following exception:

Traceback (most recent call last):
  File "/home/troll/.local/share/virtualenvs/backend-ArvMLrc1/lib/python3.6/site-packages/django/core/handlers/exception.py", line 34, in inner
    response = get_response(request)
  File "/home/troll/.local/share/virtualenvs/backend-ArvMLrc1/lib/python3.6/site-packages/django/core/handlers/base.py", line 126, in _get_response
    response = self.process_exception_by_middleware(e, request)
  File "/home/troll/.local/share/virtualenvs/backend-ArvMLrc1/lib/python3.6/site-packages/django/core/handlers/base.py", line 124, in _get_response
    response = wrapped_callback(request, *callback_args, **callback_kwargs)
  File "/home/troll/.local/share/virtualenvs/backend-ArvMLrc1/lib/python3.6/site-packages/django/views/decorators/csrf.py", line 54, in wrapped_view
    return view_func(*args, **kwargs)
  File "/home/troll/.local/share/virtualenvs/backend-ArvMLrc1/lib/python3.6/site-packages/django/views/generic/base.py", line 68, in view
    return self.dispatch(request, *args, **kwargs)
  File "/home/troll/.local/share/virtualenvs/backend-ArvMLrc1/lib/python3.6/site-packages/rest_framework/views.py", line 483, in dispatch
    response = self.handle_exception(exc)
  File "/home/troll/.local/share/virtualenvs/backend-ArvMLrc1/lib/python3.6/site-packages/rest_framework/views.py", line 443, in handle_exception
    self.raise_uncaught_exception(exc)
  File "/home/troll/.local/share/virtualenvs/backend-ArvMLrc1/lib/python3.6/site-packages/rest_framework/views.py", line 480, in dispatch
    response = handler(request, *args, **kwargs)
  File "/home/troll/procom-com/backend/procom_backend/jwt_auth/views.py", line 117, in post
    user = create_user_with_profile(validated_data)
  File "/home/troll/procom-com/backend/procom_backend/jwt_auth/utils.py", line 47, in create_user_with_profile
    user.save()
  File "/home/troll/.local/share/virtualenvs/backend-ArvMLrc1/lib/python3.6/site-packages/django/contrib/auth/base_user.py", line 73, in save
    super().save(*args, **kwargs)
  File "/home/troll/.local/share/virtualenvs/backend-ArvMLrc1/lib/python3.6/site-packages/django/db/models/base.py", line 717, in save
    force_update=force_update, update_fields=update_fields)
  File "/home/troll/.local/share/virtualenvs/backend-ArvMLrc1/lib/python3.6/site-packages/django/db/models/base.py", line 747, in save_base
    updated = self._save_table(raw, cls, force_insert, force_update, using, update_fields)
  File "/home/troll/.local/share/virtualenvs/backend-ArvMLrc1/lib/python3.6/site-packages/django/db/models/base.py", line 830, in _save_table
    result = self._do_insert(cls._base_manager, using, fields, update_pk, raw)
  File "/home/troll/.local/share/virtualenvs/backend-ArvMLrc1/lib/python3.6/site-packages/django/db/models/base.py", line 868, in _do_insert
    using=using, raw=raw)
  File "/home/troll/.local/share/virtualenvs/backend-ArvMLrc1/lib/python3.6/site-packages/django/db/models/manager.py", line 82, in manager_method
    return getattr(self.get_queryset(), name)(*args, **kwargs)
  File "/home/troll/.local/share/virtualenvs/backend-ArvMLrc1/lib/python3.6/site-packages/django/db/models/query.py", line 1133, in _insert
    return query.get_compiler(using=using).execute_sql(return_id)
  File "/home/troll/.local/share/virtualenvs/backend-ArvMLrc1/lib/python3.6/site-packages/django/db/models/sql/compiler.py", line 1285, in execute_sql
    cursor.execute(sql, params)
  File "/home/troll/.local/share/virtualenvs/backend-ArvMLrc1/lib/python3.6/site-packages/django/db/backends/utils.py", line 100, in execute
    return super().execute(sql, params)
  File "/home/troll/.local/share/virtualenvs/backend-ArvMLrc1/lib/python3.6/site-packages/django/db/backends/utils.py", line 68, in execute
    return self._execute_with_wrappers(sql, params, many=False, executor=self._execute)
  File "/home/troll/.local/share/virtualenvs/backend-ArvMLrc1/lib/python3.6/site-packages/django/db/backends/utils.py", line 77, in _execute_with_wrappers
    return executor(sql, params, many, context)
  File "/home/troll/.local/share/virtualenvs/backend-ArvMLrc1/lib/python3.6/site-packages/django/db/backends/utils.py", line 85, in _execute
    return self.cursor.execute(sql, params)
  File "/home/troll/.local/share/virtualenvs/backend-ArvMLrc1/lib/python3.6/site-packages/django/db/utils.py", line 89, in __exit__
    raise dj_exc_value.with_traceback(traceback) from exc_value
  File "/home/troll/.local/share/virtualenvs/backend-ArvMLrc1/lib/python3.6/site-packages/django/db/backends/utils.py", line 85, in _execute
    return self.cursor.execute(sql, params)
django.db.utils.IntegrityError: duplicate key value violates unique constraint "auth_user_username_key"
DETAIL:  Key (username)=(Adlxg7) already exists.

ERROR:django.request: Internal Server Error: /auth/verify-otp/ (2018-08-27 02:19:29; log.py:228)
Traceback (most recent call last):
  File "/home/troll/.local/share/virtualenvs/backend-ArvMLrc1/lib/python3.6/site-packages/django/db/backends/utils.py", line 85, in _execute
    return self.cursor.execute(sql, params)
psycopg2.IntegrityError: duplicate key value violates unique constraint "auth_user_username_key"
DETAIL:  Key (username)=(Adlxg7) already exists.


The above exception was the direct cause of the following exception:

Traceback (most recent call last):
  File "/home/troll/.local/share/virtualenvs/backend-ArvMLrc1/lib/python3.6/site-packages/django/core/handlers/exception.py", line 34, in inner
    response = get_response(request)
  File "/home/troll/.local/share/virtualenvs/backend-ArvMLrc1/lib/python3.6/site-packages/django/core/handlers/base.py", line 126, in _get_response
    response = self.process_exception_by_middleware(e, request)
  File "/home/troll/.local/share/virtualenvs/backend-ArvMLrc1/lib/python3.6/site-packages/django/core/handlers/base.py", line 124, in _get_response
    response = wrapped_callback(request, *callback_args, **callback_kwargs)
  File "/home/troll/.local/share/virtualenvs/backend-ArvMLrc1/lib/python3.6/site-packages/django/views/decorators/csrf.py", line 54, in wrapped_view
    return view_func(*args, **kwargs)
  File "/home/troll/.local/share/virtualenvs/backend-ArvMLrc1/lib/python3.6/site-packages/django/views/generic/base.py", line 68, in view
    return self.dispatch(request, *args, **kwargs)
  File "/home/troll/.local/share/virtualenvs/backend-ArvMLrc1/lib/python3.6/site-packages/rest_framework/views.py", line 483, in dispatch
    response = self.handle_exception(exc)
  File "/home/troll/.local/share/virtualenvs/backend-ArvMLrc1/lib/python3.6/site-packages/rest_framework/views.py", line 443, in handle_exception
    self.raise_uncaught_exception(exc)
  File "/home/troll/.local/share/virtualenvs/backend-ArvMLrc1/lib/python3.6/site-packages/rest_framework/views.py", line 480, in dispatch
    response = handler(request, *args, **kwargs)
  File "/home/troll/procom-com/backend/procom_backend/jwt_auth/views.py", line 117, in post
    user = create_user_with_profile(validated_data)
  File "/home/troll/procom-com/backend/procom_backend/jwt_auth/utils.py", line 47, in create_user_with_profile
    user.save()
  File "/home/troll/.local/share/virtualenvs/backend-ArvMLrc1/lib/python3.6/site-packages/django/contrib/auth/base_user.py", line 73, in save
    super().save(*args, **kwargs)
  File "/home/troll/.local/share/virtualenvs/backend-ArvMLrc1/lib/python3.6/site-packages/django/db/models/base.py", line 717, in save
    force_update=force_update, update_fields=update_fields)
  File "/home/troll/.local/share/virtualenvs/backend-ArvMLrc1/lib/python3.6/site-packages/django/db/models/base.py", line 747, in save_base
    updated = self._save_table(raw, cls, force_insert, force_update, using, update_fields)
  File "/home/troll/.local/share/virtualenvs/backend-ArvMLrc1/lib/python3.6/site-packages/django/db/models/base.py", line 830, in _save_table
    result = self._do_insert(cls._base_manager, using, fields, update_pk, raw)
  File "/home/troll/.local/share/virtualenvs/backend-ArvMLrc1/lib/python3.6/site-packages/django/db/models/base.py", line 868, in _do_insert
    using=using, raw=raw)
  File "/home/troll/.local/share/virtualenvs/backend-ArvMLrc1/lib/python3.6/site-packages/django/db/models/manager.py", line 82, in manager_method
    return getattr(self.get_queryset(), name)(*args, **kwargs)
  File "/home/troll/.local/share/virtualenvs/backend-ArvMLrc1/lib/python3.6/site-packages/django/db/models/query.py", line 1133, in _insert
    return query.get_compiler(using=using).execute_sql(return_id)
  File "/home/troll/.local/share/virtualenvs/backend-ArvMLrc1/lib/python3.6/site-packages/django/db/models/sql/compiler.py", line 1285, in execute_sql
    cursor.execute(sql, params)
  File "/home/troll/.local/share/virtualenvs/backend-ArvMLrc1/lib/python3.6/site-packages/django/db/backends/utils.py", line 100, in execute
    return super().execute(sql, params)
  File "/home/troll/.local/share/virtualenvs/backend-ArvMLrc1/lib/python3.6/site-packages/django/db/backends/utils.py", line 68, in execute
    return self._execute_with_wrappers(sql, params, many=False, executor=self._execute)
  File "/home/troll/.local/share/virtualenvs/backend-ArvMLrc1/lib/python3.6/site-packages/django/db/backends/utils.py", line 77, in _execute_with_wrappers
    return executor(sql, params, many, context)
  File "/home/troll/.local/share/virtualenvs/backend-ArvMLrc1/lib/python3.6/site-packages/django/db/backends/utils.py", line 85, in _execute
    return self.cursor.execute(sql, params)
  File "/home/troll/.local/share/virtualenvs/backend-ArvMLrc1/lib/python3.6/site-packages/django/db/utils.py", line 89, in __exit__
    raise dj_exc_value.with_traceback(traceback) from exc_value
  File "/home/troll/.local/share/virtualenvs/backend-ArvMLrc1/lib/python3.6/site-packages/django/db/backends/utils.py", line 85, in _execute
    return self.cursor.execute(sql, params)
django.db.utils.IntegrityError: duplicate key value violates unique constraint "auth_user_username_key"
DETAIL:  Key (username)=(Adlxg7) already exists.

ERROR:django.request: Internal Server Error: /auth/verify-otp/ (2018-08-27 02:19:29; log.py:228)
Traceback (most recent call last):
  File "/home/troll/.local/share/virtualenvs/backend-ArvMLrc1/lib/python3.6/site-packages/django/db/backends/utils.py", line 85, in _execute
    return self.cursor.execute(sql, params)
psycopg2.IntegrityError: duplicate key value violates unique constraint "auth_user_username_key"
DETAIL:  Key (username)=(Adlxg7) already exists.


The above exception was the direct cause of the following exception:

Traceback (most recent call last):
  File "/home/troll/.local/share/virtualenvs/backend-ArvMLrc1/lib/python3.6/site-packages/django/core/handlers/exception.py", line 34, in inner
    response = get_response(request)
  File "/home/troll/.local/share/virtualenvs/backend-ArvMLrc1/lib/python3.6/site-packages/django/core/handlers/base.py", line 126, in _get_response
    response = self.process_exception_by_middleware(e, request)
  File "/home/troll/.local/share/virtualenvs/backend-ArvMLrc1/lib/python3.6/site-packages/django/core/handlers/base.py", line 124, in _get_response
    response = wrapped_callback(request, *callback_args, **callback_kwargs)
  File "/home/troll/.local/share/virtualenvs/backend-ArvMLrc1/lib/python3.6/site-packages/django/views/decorators/csrf.py", line 54, in wrapped_view
    return view_func(*args, **kwargs)
  File "/home/troll/.local/share/virtualenvs/backend-ArvMLrc1/lib/python3.6/site-packages/django/views/generic/base.py", line 68, in view
    return self.dispatch(request, *args, **kwargs)
  File "/home/troll/.local/share/virtualenvs/backend-ArvMLrc1/lib/python3.6/site-packages/rest_framework/views.py", line 483, in dispatch
    response = self.handle_exception(exc)
  File "/home/troll/.local/share/virtualenvs/backend-ArvMLrc1/lib/python3.6/site-packages/rest_framework/views.py", line 443, in handle_exception
    self.raise_uncaught_exception(exc)
  File "/home/troll/.local/share/virtualenvs/backend-ArvMLrc1/lib/python3.6/site-packages/rest_framework/views.py", line 480, in dispatch
    response = handler(request, *args, **kwargs)
  File "/home/troll/procom-com/backend/procom_backend/jwt_auth/views.py", line 117, in post
    user = create_user_with_profile(validated_data)
  File "/home/troll/procom-com/backend/procom_backend/jwt_auth/utils.py", line 47, in create_user_with_profile
    user.save()
  File "/home/troll/.local/share/virtualenvs/backend-ArvMLrc1/lib/python3.6/site-packages/django/contrib/auth/base_user.py", line 73, in save
    super().save(*args, **kwargs)
  File "/home/troll/.local/share/virtualenvs/backend-ArvMLrc1/lib/python3.6/site-packages/django/db/models/base.py", line 717, in save
    force_update=force_update, update_fields=update_fields)
  File "/home/troll/.local/share/virtualenvs/backend-ArvMLrc1/lib/python3.6/site-packages/django/db/models/base.py", line 747, in save_base
    updated = self._save_table(raw, cls, force_insert, force_update, using, update_fields)
  File "/home/troll/.local/share/virtualenvs/backend-ArvMLrc1/lib/python3.6/site-packages/django/db/models/base.py", line 830, in _save_table
    result = self._do_insert(cls._base_manager, using, fields, update_pk, raw)
  File "/home/troll/.local/share/virtualenvs/backend-ArvMLrc1/lib/python3.6/site-packages/django/db/models/base.py", line 868, in _do_insert
    using=using, raw=raw)
  File "/home/troll/.local/share/virtualenvs/backend-ArvMLrc1/lib/python3.6/site-packages/django/db/models/manager.py", line 82, in manager_method
    return getattr(self.get_queryset(), name)(*args, **kwargs)
  File "/home/troll/.local/share/virtualenvs/backend-ArvMLrc1/lib/python3.6/site-packages/django/db/models/query.py", line 1133, in _insert
    return query.get_compiler(using=using).execute_sql(return_id)
  File "/home/troll/.local/share/virtualenvs/backend-ArvMLrc1/lib/python3.6/site-packages/django/db/models/sql/compiler.py", line 1285, in execute_sql
    cursor.execute(sql, params)
  File "/home/troll/.local/share/virtualenvs/backend-ArvMLrc1/lib/python3.6/site-packages/django/db/backends/utils.py", line 100, in execute
    return super().execute(sql, params)
  File "/home/troll/.local/share/virtualenvs/backend-ArvMLrc1/lib/python3.6/site-packages/django/db/backends/utils.py", line 68, in execute
    return self._execute_with_wrappers(sql, params, many=False, executor=self._execute)
  File "/home/troll/.local/share/virtualenvs/backend-ArvMLrc1/lib/python3.6/site-packages/django/db/backends/utils.py", line 77, in _execute_with_wrappers
    return executor(sql, params, many, context)
  File "/home/troll/.local/share/virtualenvs/backend-ArvMLrc1/lib/python3.6/site-packages/django/db/backends/utils.py", line 85, in _execute
    return self.cursor.execute(sql, params)
  File "/home/troll/.local/share/virtualenvs/backend-ArvMLrc1/lib/python3.6/site-packages/django/db/utils.py", line 89, in __exit__
    raise dj_exc_value.with_traceback(traceback) from exc_value
  File "/home/troll/.local/share/virtualenvs/backend-ArvMLrc1/lib/python3.6/site-packages/django/db/backends/utils.py", line 85, in _execute
    return self.cursor.execute(sql, params)
django.db.utils.IntegrityError: duplicate key value violates unique constraint "auth_user_username_key"
DETAIL:  Key (username)=(Adlxg7) already exists.

ERROR:django.request: Internal Server Error: /auth/verify-otp/ (2018-08-27 02:19:29; log.py:228)
Traceback (most recent call last):
  File "/home/troll/.local/share/virtualenvs/backend-ArvMLrc1/lib/python3.6/site-packages/django/db/backends/utils.py", line 85, in _execute
    return self.cursor.execute(sql, params)
psycopg2.IntegrityError: duplicate key value violates unique constraint "auth_user_username_key"
DETAIL:  Key (username)=(Adlxg7) already exists.


The above exception was the direct cause of the following exception:

Traceback (most recent call last):
  File "/home/troll/.local/share/virtualenvs/backend-ArvMLrc1/lib/python3.6/site-packages/django/core/handlers/exception.py", line 34, in inner
    response = get_response(request)
  File "/home/troll/.local/share/virtualenvs/backend-ArvMLrc1/lib/python3.6/site-packages/django/core/handlers/base.py", line 126, in _get_response
    response = self.process_exception_by_middleware(e, request)
  File "/home/troll/.local/share/virtualenvs/backend-ArvMLrc1/lib/python3.6/site-packages/django/core/handlers/base.py", line 124, in _get_response
    response = wrapped_callback(request, *callback_args, **callback_kwargs)
  File "/home/troll/.local/share/virtualenvs/backend-ArvMLrc1/lib/python3.6/site-packages/django/views/decorators/csrf.py", line 54, in wrapped_view
    return view_func(*args, **kwargs)
  File "/home/troll/.local/share/virtualenvs/backend-ArvMLrc1/lib/python3.6/site-packages/django/views/generic/base.py", line 68, in view
    return self.dispatch(request, *args, **kwargs)
  File "/home/troll/.local/share/virtualenvs/backend-ArvMLrc1/lib/python3.6/site-packages/rest_framework/views.py", line 483, in dispatch
    response = self.handle_exception(exc)
  File "/home/troll/.local/share/virtualenvs/backend-ArvMLrc1/lib/python3.6/site-packages/rest_framework/views.py", line 443, in handle_exception
    self.raise_uncaught_exception(exc)
  File "/home/troll/.local/share/virtualenvs/backend-ArvMLrc1/lib/python3.6/site-packages/rest_framework/views.py", line 480, in dispatch
    response = handler(request, *args, **kwargs)
  File "/home/troll/procom-com/backend/procom_backend/jwt_auth/views.py", line 117, in post
    user = create_user_with_profile(validated_data)
  File "/home/troll/procom-com/backend/procom_backend/jwt_auth/utils.py", line 47, in create_user_with_profile
    user.save()
  File "/home/troll/.local/share/virtualenvs/backend-ArvMLrc1/lib/python3.6/site-packages/django/contrib/auth/base_user.py", line 73, in save
    super().save(*args, **kwargs)
  File "/home/troll/.local/share/virtualenvs/backend-ArvMLrc1/lib/python3.6/site-packages/django/db/models/base.py", line 717, in save
    force_update=force_update, update_fields=update_fields)
  File "/home/troll/.local/share/virtualenvs/backend-ArvMLrc1/lib/python3.6/site-packages/django/db/models/base.py", line 747, in save_base
    updated = self._save_table(raw, cls, force_insert, force_update, using, update_fields)
  File "/home/troll/.local/share/virtualenvs/backend-ArvMLrc1/lib/python3.6/site-packages/django/db/models/base.py", line 830, in _save_table
    result = self._do_insert(cls._base_manager, using, fields, update_pk, raw)
  File "/home/troll/.local/share/virtualenvs/backend-ArvMLrc1/lib/python3.6/site-packages/django/db/models/base.py", line 868, in _do_insert
    using=using, raw=raw)
  File "/home/troll/.local/share/virtualenvs/backend-ArvMLrc1/lib/python3.6/site-packages/django/db/models/manager.py", line 82, in manager_method
    return getattr(self.get_queryset(), name)(*args, **kwargs)
  File "/home/troll/.local/share/virtualenvs/backend-ArvMLrc1/lib/python3.6/site-packages/django/db/models/query.py", line 1133, in _insert
    return query.get_compiler(using=using).execute_sql(return_id)
  File "/home/troll/.local/share/virtualenvs/backend-ArvMLrc1/lib/python3.6/site-packages/django/db/models/sql/compiler.py", line 1285, in execute_sql
    cursor.execute(sql, params)
  File "/home/troll/.local/share/virtualenvs/backend-ArvMLrc1/lib/python3.6/site-packages/django/db/backends/utils.py", line 100, in execute
    return super().execute(sql, params)
  File "/home/troll/.local/share/virtualenvs/backend-ArvMLrc1/lib/python3.6/site-packages/django/db/backends/utils.py", line 68, in execute
    return self._execute_with_wrappers(sql, params, many=False, executor=self._execute)
  File "/home/troll/.local/share/virtualenvs/backend-ArvMLrc1/lib/python3.6/site-packages/django/db/backends/utils.py", line 77, in _execute_with_wrappers
    return executor(sql, params, many, context)
  File "/home/troll/.local/share/virtualenvs/backend-ArvMLrc1/lib/python3.6/site-packages/django/db/backends/utils.py", line 85, in _execute
    return self.cursor.execute(sql, params)
  File "/home/troll/.local/share/virtualenvs/backend-ArvMLrc1/lib/python3.6/site-packages/django/db/utils.py", line 89, in __exit__
    raise dj_exc_value.with_traceback(traceback) from exc_value
  File "/home/troll/.local/share/virtualenvs/backend-ArvMLrc1/lib/python3.6/site-packages/django/db/backends/utils.py", line 85, in _execute
    return self.cursor.execute(sql, params)
django.db.utils.IntegrityError: duplicate key value violates unique constraint "auth_user_username_key"
DETAIL:  Key (username)=(Adlxg7) already exists.

ERROR:django.request: Internal Server Error: /auth/verify-otp/ (2018-08-27 02:19:29; log.py:228)
Traceback (most recent call last):
  File "/home/troll/.local/share/virtualenvs/backend-ArvMLrc1/lib/python3.6/site-packages/django/db/backends/utils.py", line 85, in _execute
    return self.cursor.execute(sql, params)
psycopg2.IntegrityError: duplicate key value violates unique constraint "auth_user_username_key"
DETAIL:  Key (username)=(Adlxg7) already exists.


The above exception was the direct cause of the following exception:

Traceback (most recent call last):
  File "/home/troll/.local/share/virtualenvs/backend-ArvMLrc1/lib/python3.6/site-packages/django/core/handlers/exception.py", line 34, in inner
    response = get_response(request)
  File "/home/troll/.local/share/virtualenvs/backend-ArvMLrc1/lib/python3.6/site-packages/django/core/handlers/base.py", line 126, in _get_response
    response = self.process_exception_by_middleware(e, request)
  File "/home/troll/.local/share/virtualenvs/backend-ArvMLrc1/lib/python3.6/site-packages/django/core/handlers/base.py", line 124, in _get_response
    response = wrapped_callback(request, *callback_args, **callback_kwargs)
  File "/home/troll/.local/share/virtualenvs/backend-ArvMLrc1/lib/python3.6/site-packages/django/views/decorators/csrf.py", line 54, in wrapped_view
    return view_func(*args, **kwargs)
  File "/home/troll/.local/share/virtualenvs/backend-ArvMLrc1/lib/python3.6/site-packages/django/views/generic/base.py", line 68, in view
    return self.dispatch(request, *args, **kwargs)
  File "/home/troll/.local/share/virtualenvs/backend-ArvMLrc1/lib/python3.6/site-packages/rest_framework/views.py", line 483, in dispatch
    response = self.handle_exception(exc)
  File "/home/troll/.local/share/virtualenvs/backend-ArvMLrc1/lib/python3.6/site-packages/rest_framework/views.py", line 443, in handle_exception
    self.raise_uncaught_exception(exc)
  File "/home/troll/.local/share/virtualenvs/backend-ArvMLrc1/lib/python3.6/site-packages/rest_framework/views.py", line 480, in dispatch
    response = handler(request, *args, **kwargs)
  File "/home/troll/procom-com/backend/procom_backend/jwt_auth/views.py", line 117, in post
    user = create_user_with_profile(validated_data)
  File "/home/troll/procom-com/backend/procom_backend/jwt_auth/utils.py", line 47, in create_user_with_profile
    user.save()
  File "/home/troll/.local/share/virtualenvs/backend-ArvMLrc1/lib/python3.6/site-packages/django/contrib/auth/base_user.py", line 73, in save
    super().save(*args, **kwargs)
  File "/home/troll/.local/share/virtualenvs/backend-ArvMLrc1/lib/python3.6/site-packages/django/db/models/base.py", line 717, in save
    force_update=force_update, update_fields=update_fields)
  File "/home/troll/.local/share/virtualenvs/backend-ArvMLrc1/lib/python3.6/site-packages/django/db/models/base.py", line 747, in save_base
    updated = self._save_table(raw, cls, force_insert, force_update, using, update_fields)
  File "/home/troll/.local/share/virtualenvs/backend-ArvMLrc1/lib/python3.6/site-packages/django/db/models/base.py", line 830, in _save_table
    result = self._do_insert(cls._base_manager, using, fields, update_pk, raw)
  File "/home/troll/.local/share/virtualenvs/backend-ArvMLrc1/lib/python3.6/site-packages/django/db/models/base.py", line 868, in _do_insert
    using=using, raw=raw)
  File "/home/troll/.local/share/virtualenvs/backend-ArvMLrc1/lib/python3.6/site-packages/django/db/models/manager.py", line 82, in manager_method
    return getattr(self.get_queryset(), name)(*args, **kwargs)
  File "/home/troll/.local/share/virtualenvs/backend-ArvMLrc1/lib/python3.6/site-packages/django/db/models/query.py", line 1133, in _insert
    return query.get_compiler(using=using).execute_sql(return_id)
  File "/home/troll/.local/share/virtualenvs/backend-ArvMLrc1/lib/python3.6/site-packages/django/db/models/sql/compiler.py", line 1285, in execute_sql
    cursor.execute(sql, params)
  File "/home/troll/.local/share/virtualenvs/backend-ArvMLrc1/lib/python3.6/site-packages/django/db/backends/utils.py", line 100, in execute
    return super().execute(sql, params)
  File "/home/troll/.local/share/virtualenvs/backend-ArvMLrc1/lib/python3.6/site-packages/django/db/backends/utils.py", line 68, in execute
    return self._execute_with_wrappers(sql, params, many=False, executor=self._execute)
  File "/home/troll/.local/share/virtualenvs/backend-ArvMLrc1/lib/python3.6/site-packages/django/db/backends/utils.py", line 77, in _execute_with_wrappers
    return executor(sql, params, many, context)
  File "/home/troll/.local/share/virtualenvs/backend-ArvMLrc1/lib/python3.6/site-packages/django/db/backends/utils.py", line 85, in _execute
    return self.cursor.execute(sql, params)
  File "/home/troll/.local/share/virtualenvs/backend-ArvMLrc1/lib/python3.6/site-packages/django/db/utils.py", line 89, in __exit__
    raise dj_exc_value.with_traceback(traceback) from exc_value
  File "/home/troll/.local/share/virtualenvs/backend-ArvMLrc1/lib/python3.6/site-packages/django/db/backends/utils.py", line 85, in _execute
    return self.cursor.execute(sql, params)
django.db.utils.IntegrityError: duplicate key value violates unique constraint "auth_user_username_key"
DETAIL:  Key (username)=(Adlxg7) already exists.

DEBUG:jwt_auth.views: OrderedDict([('first_name', 'Ashish'), ('last_name', ''), ('email', 'ting@tong.com'), ('mobile', '9818611162'), ('business_name', 'Some business'), ('password', 'Tingtong'), ('otp', '270561')]) (2018-08-27 02:21:32; views.py:57)
ERROR:django.request: Internal Server Error: /auth/verify-otp/ (2018-08-27 02:21:47; log.py:228)
Traceback (most recent call last):
  File "/home/troll/.local/share/virtualenvs/backend-ArvMLrc1/lib/python3.6/site-packages/django/core/handlers/exception.py", line 34, in inner
    response = get_response(request)
  File "/home/troll/.local/share/virtualenvs/backend-ArvMLrc1/lib/python3.6/site-packages/django/core/handlers/base.py", line 126, in _get_response
    response = self.process_exception_by_middleware(e, request)
  File "/home/troll/.local/share/virtualenvs/backend-ArvMLrc1/lib/python3.6/site-packages/django/core/handlers/base.py", line 124, in _get_response
    response = wrapped_callback(request, *callback_args, **callback_kwargs)
  File "/home/troll/.local/share/virtualenvs/backend-ArvMLrc1/lib/python3.6/site-packages/django/views/decorators/csrf.py", line 54, in wrapped_view
    return view_func(*args, **kwargs)
  File "/home/troll/.local/share/virtualenvs/backend-ArvMLrc1/lib/python3.6/site-packages/django/views/generic/base.py", line 68, in view
    return self.dispatch(request, *args, **kwargs)
  File "/home/troll/.local/share/virtualenvs/backend-ArvMLrc1/lib/python3.6/site-packages/rest_framework/views.py", line 483, in dispatch
    response = self.handle_exception(exc)
  File "/home/troll/.local/share/virtualenvs/backend-ArvMLrc1/lib/python3.6/site-packages/rest_framework/views.py", line 443, in handle_exception
    self.raise_uncaught_exception(exc)
  File "/home/troll/.local/share/virtualenvs/backend-ArvMLrc1/lib/python3.6/site-packages/rest_framework/views.py", line 480, in dispatch
    response = handler(request, *args, **kwargs)
  File "/home/troll/procom-com/backend/procom_backend/jwt_auth/views.py", line 117, in post
    user = create_user_with_profile(validated_data)
  File "/home/troll/procom-com/backend/procom_backend/jwt_auth/utils.py", line 49, in create_user_with_profile
    gstin=validated_data['gstin'],
KeyError: 'gstin'
ERROR:django.request: Internal Server Error: /auth/verify-otp/ (2018-08-27 02:21:47; log.py:228)
Traceback (most recent call last):
  File "/home/troll/.local/share/virtualenvs/backend-ArvMLrc1/lib/python3.6/site-packages/django/db/backends/utils.py", line 85, in _execute
    return self.cursor.execute(sql, params)
psycopg2.IntegrityError: duplicate key value violates unique constraint "auth_user_username_key"
DETAIL:  Key (username)=(82T1jQ) already exists.


The above exception was the direct cause of the following exception:

Traceback (most recent call last):
  File "/home/troll/.local/share/virtualenvs/backend-ArvMLrc1/lib/python3.6/site-packages/django/core/handlers/exception.py", line 34, in inner
    response = get_response(request)
  File "/home/troll/.local/share/virtualenvs/backend-ArvMLrc1/lib/python3.6/site-packages/django/core/handlers/base.py", line 126, in _get_response
    response = self.process_exception_by_middleware(e, request)
  File "/home/troll/.local/share/virtualenvs/backend-ArvMLrc1/lib/python3.6/site-packages/django/core/handlers/base.py", line 124, in _get_response
    response = wrapped_callback(request, *callback_args, **callback_kwargs)
  File "/home/troll/.local/share/virtualenvs/backend-ArvMLrc1/lib/python3.6/site-packages/django/views/decorators/csrf.py", line 54, in wrapped_view
    return view_func(*args, **kwargs)
  File "/home/troll/.local/share/virtualenvs/backend-ArvMLrc1/lib/python3.6/site-packages/django/views/generic/base.py", line 68, in view
    return self.dispatch(request, *args, **kwargs)
  File "/home/troll/.local/share/virtualenvs/backend-ArvMLrc1/lib/python3.6/site-packages/rest_framework/views.py", line 483, in dispatch
    response = self.handle_exception(exc)
  File "/home/troll/.local/share/virtualenvs/backend-ArvMLrc1/lib/python3.6/site-packages/rest_framework/views.py", line 443, in handle_exception
    self.raise_uncaught_exception(exc)
  File "/home/troll/.local/share/virtualenvs/backend-ArvMLrc1/lib/python3.6/site-packages/rest_framework/views.py", line 480, in dispatch
    response = handler(request, *args, **kwargs)
  File "/home/troll/procom-com/backend/procom_backend/jwt_auth/views.py", line 117, in post
    user = create_user_with_profile(validated_data)
  File "/home/troll/procom-com/backend/procom_backend/jwt_auth/utils.py", line 47, in create_user_with_profile
    user.save()
  File "/home/troll/.local/share/virtualenvs/backend-ArvMLrc1/lib/python3.6/site-packages/django/contrib/auth/base_user.py", line 73, in save
    super().save(*args, **kwargs)
  File "/home/troll/.local/share/virtualenvs/backend-ArvMLrc1/lib/python3.6/site-packages/django/db/models/base.py", line 717, in save
    force_update=force_update, update_fields=update_fields)
  File "/home/troll/.local/share/virtualenvs/backend-ArvMLrc1/lib/python3.6/site-packages/django/db/models/base.py", line 747, in save_base
    updated = self._save_table(raw, cls, force_insert, force_update, using, update_fields)
  File "/home/troll/.local/share/virtualenvs/backend-ArvMLrc1/lib/python3.6/site-packages/django/db/models/base.py", line 830, in _save_table
    result = self._do_insert(cls._base_manager, using, fields, update_pk, raw)
  File "/home/troll/.local/share/virtualenvs/backend-ArvMLrc1/lib/python3.6/site-packages/django/db/models/base.py", line 868, in _do_insert
    using=using, raw=raw)
  File "/home/troll/.local/share/virtualenvs/backend-ArvMLrc1/lib/python3.6/site-packages/django/db/models/manager.py", line 82, in manager_method
    return getattr(self.get_queryset(), name)(*args, **kwargs)
  File "/home/troll/.local/share/virtualenvs/backend-ArvMLrc1/lib/python3.6/site-packages/django/db/models/query.py", line 1133, in _insert
    return query.get_compiler(using=using).execute_sql(return_id)
  File "/home/troll/.local/share/virtualenvs/backend-ArvMLrc1/lib/python3.6/site-packages/django/db/models/sql/compiler.py", line 1285, in execute_sql
    cursor.execute(sql, params)
  File "/home/troll/.local/share/virtualenvs/backend-ArvMLrc1/lib/python3.6/site-packages/django/db/backends/utils.py", line 100, in execute
    return super().execute(sql, params)
  File "/home/troll/.local/share/virtualenvs/backend-ArvMLrc1/lib/python3.6/site-packages/django/db/backends/utils.py", line 68, in execute
    return self._execute_with_wrappers(sql, params, many=False, executor=self._execute)
  File "/home/troll/.local/share/virtualenvs/backend-ArvMLrc1/lib/python3.6/site-packages/django/db/backends/utils.py", line 77, in _execute_with_wrappers
    return executor(sql, params, many, context)
  File "/home/troll/.local/share/virtualenvs/backend-ArvMLrc1/lib/python3.6/site-packages/django/db/backends/utils.py", line 85, in _execute
    return self.cursor.execute(sql, params)
  File "/home/troll/.local/share/virtualenvs/backend-ArvMLrc1/lib/python3.6/site-packages/django/db/utils.py", line 89, in __exit__
    raise dj_exc_value.with_traceback(traceback) from exc_value
  File "/home/troll/.local/share/virtualenvs/backend-ArvMLrc1/lib/python3.6/site-packages/django/db/backends/utils.py", line 85, in _execute
    return self.cursor.execute(sql, params)
django.db.utils.IntegrityError: duplicate key value violates unique constraint "auth_user_username_key"
DETAIL:  Key (username)=(82T1jQ) already exists.

ERROR:django.request: Internal Server Error: /auth/verify-otp/ (2018-08-27 02:21:47; log.py:228)
Traceback (most recent call last):
  File "/home/troll/.local/share/virtualenvs/backend-ArvMLrc1/lib/python3.6/site-packages/django/db/backends/utils.py", line 85, in _execute
    return self.cursor.execute(sql, params)
psycopg2.IntegrityError: duplicate key value violates unique constraint "auth_user_username_key"
DETAIL:  Key (username)=(82T1jQ) already exists.


The above exception was the direct cause of the following exception:

Traceback (most recent call last):
  File "/home/troll/.local/share/virtualenvs/backend-ArvMLrc1/lib/python3.6/site-packages/django/core/handlers/exception.py", line 34, in inner
    response = get_response(request)
  File "/home/troll/.local/share/virtualenvs/backend-ArvMLrc1/lib/python3.6/site-packages/django/core/handlers/base.py", line 126, in _get_response
    response = self.process_exception_by_middleware(e, request)
  File "/home/troll/.local/share/virtualenvs/backend-ArvMLrc1/lib/python3.6/site-packages/django/core/handlers/base.py", line 124, in _get_response
    response = wrapped_callback(request, *callback_args, **callback_kwargs)
  File "/home/troll/.local/share/virtualenvs/backend-ArvMLrc1/lib/python3.6/site-packages/django/views/decorators/csrf.py", line 54, in wrapped_view
    return view_func(*args, **kwargs)
  File "/home/troll/.local/share/virtualenvs/backend-ArvMLrc1/lib/python3.6/site-packages/django/views/generic/base.py", line 68, in view
    return self.dispatch(request, *args, **kwargs)
  File "/home/troll/.local/share/virtualenvs/backend-ArvMLrc1/lib/python3.6/site-packages/rest_framework/views.py", line 483, in dispatch
    response = self.handle_exception(exc)
  File "/home/troll/.local/share/virtualenvs/backend-ArvMLrc1/lib/python3.6/site-packages/rest_framework/views.py", line 443, in handle_exception
    self.raise_uncaught_exception(exc)
  File "/home/troll/.local/share/virtualenvs/backend-ArvMLrc1/lib/python3.6/site-packages/rest_framework/views.py", line 480, in dispatch
    response = handler(request, *args, **kwargs)
  File "/home/troll/procom-com/backend/procom_backend/jwt_auth/views.py", line 117, in post
    user = create_user_with_profile(validated_data)
  File "/home/troll/procom-com/backend/procom_backend/jwt_auth/utils.py", line 47, in create_user_with_profile
    user.save()
  File "/home/troll/.local/share/virtualenvs/backend-ArvMLrc1/lib/python3.6/site-packages/django/contrib/auth/base_user.py", line 73, in save
    super().save(*args, **kwargs)
  File "/home/troll/.local/share/virtualenvs/backend-ArvMLrc1/lib/python3.6/site-packages/django/db/models/base.py", line 717, in save
    force_update=force_update, update_fields=update_fields)
  File "/home/troll/.local/share/virtualenvs/backend-ArvMLrc1/lib/python3.6/site-packages/django/db/models/base.py", line 747, in save_base
    updated = self._save_table(raw, cls, force_insert, force_update, using, update_fields)
  File "/home/troll/.local/share/virtualenvs/backend-ArvMLrc1/lib/python3.6/site-packages/django/db/models/base.py", line 830, in _save_table
    result = self._do_insert(cls._base_manager, using, fields, update_pk, raw)
  File "/home/troll/.local/share/virtualenvs/backend-ArvMLrc1/lib/python3.6/site-packages/django/db/models/base.py", line 868, in _do_insert
    using=using, raw=raw)
  File "/home/troll/.local/share/virtualenvs/backend-ArvMLrc1/lib/python3.6/site-packages/django/db/models/manager.py", line 82, in manager_method
    return getattr(self.get_queryset(), name)(*args, **kwargs)
  File "/home/troll/.local/share/virtualenvs/backend-ArvMLrc1/lib/python3.6/site-packages/django/db/models/query.py", line 1133, in _insert
    return query.get_compiler(using=using).execute_sql(return_id)
  File "/home/troll/.local/share/virtualenvs/backend-ArvMLrc1/lib/python3.6/site-packages/django/db/models/sql/compiler.py", line 1285, in execute_sql
    cursor.execute(sql, params)
  File "/home/troll/.local/share/virtualenvs/backend-ArvMLrc1/lib/python3.6/site-packages/django/db/backends/utils.py", line 100, in execute
    return super().execute(sql, params)
  File "/home/troll/.local/share/virtualenvs/backend-ArvMLrc1/lib/python3.6/site-packages/django/db/backends/utils.py", line 68, in execute
    return self._execute_with_wrappers(sql, params, many=False, executor=self._execute)
  File "/home/troll/.local/share/virtualenvs/backend-ArvMLrc1/lib/python3.6/site-packages/django/db/backends/utils.py", line 77, in _execute_with_wrappers
    return executor(sql, params, many, context)
  File "/home/troll/.local/share/virtualenvs/backend-ArvMLrc1/lib/python3.6/site-packages/django/db/backends/utils.py", line 85, in _execute
    return self.cursor.execute(sql, params)
  File "/home/troll/.local/share/virtualenvs/backend-ArvMLrc1/lib/python3.6/site-packages/django/db/utils.py", line 89, in __exit__
    raise dj_exc_value.with_traceback(traceback) from exc_value
  File "/home/troll/.local/share/virtualenvs/backend-ArvMLrc1/lib/python3.6/site-packages/django/db/backends/utils.py", line 85, in _execute
    return self.cursor.execute(sql, params)
django.db.utils.IntegrityError: duplicate key value violates unique constraint "auth_user_username_key"
DETAIL:  Key (username)=(82T1jQ) already exists.

ERROR:django.request: Internal Server Error: /auth/verify-otp/ (2018-08-27 02:21:47; log.py:228)
Traceback (most recent call last):
  File "/home/troll/.local/share/virtualenvs/backend-ArvMLrc1/lib/python3.6/site-packages/django/db/backends/utils.py", line 85, in _execute
    return self.cursor.execute(sql, params)
psycopg2.IntegrityError: duplicate key value violates unique constraint "auth_user_username_key"
DETAIL:  Key (username)=(82T1jQ) already exists.


The above exception was the direct cause of the following exception:

Traceback (most recent call last):
  File "/home/troll/.local/share/virtualenvs/backend-ArvMLrc1/lib/python3.6/site-packages/django/core/handlers/exception.py", line 34, in inner
    response = get_response(request)
  File "/home/troll/.local/share/virtualenvs/backend-ArvMLrc1/lib/python3.6/site-packages/django/core/handlers/base.py", line 126, in _get_response
    response = self.process_exception_by_middleware(e, request)
  File "/home/troll/.local/share/virtualenvs/backend-ArvMLrc1/lib/python3.6/site-packages/django/core/handlers/base.py", line 124, in _get_response
    response = wrapped_callback(request, *callback_args, **callback_kwargs)
  File "/home/troll/.local/share/virtualenvs/backend-ArvMLrc1/lib/python3.6/site-packages/django/views/decorators/csrf.py", line 54, in wrapped_view
    return view_func(*args, **kwargs)
  File "/home/troll/.local/share/virtualenvs/backend-ArvMLrc1/lib/python3.6/site-packages/django/views/generic/base.py", line 68, in view
    return self.dispatch(request, *args, **kwargs)
  File "/home/troll/.local/share/virtualenvs/backend-ArvMLrc1/lib/python3.6/site-packages/rest_framework/views.py", line 483, in dispatch
    response = self.handle_exception(exc)
  File "/home/troll/.local/share/virtualenvs/backend-ArvMLrc1/lib/python3.6/site-packages/rest_framework/views.py", line 443, in handle_exception
    self.raise_uncaught_exception(exc)
  File "/home/troll/.local/share/virtualenvs/backend-ArvMLrc1/lib/python3.6/site-packages/rest_framework/views.py", line 480, in dispatch
    response = handler(request, *args, **kwargs)
  File "/home/troll/procom-com/backend/procom_backend/jwt_auth/views.py", line 117, in post
    user = create_user_with_profile(validated_data)
  File "/home/troll/procom-com/backend/procom_backend/jwt_auth/utils.py", line 47, in create_user_with_profile
    user.save()
  File "/home/troll/.local/share/virtualenvs/backend-ArvMLrc1/lib/python3.6/site-packages/django/contrib/auth/base_user.py", line 73, in save
    super().save(*args, **kwargs)
  File "/home/troll/.local/share/virtualenvs/backend-ArvMLrc1/lib/python3.6/site-packages/django/db/models/base.py", line 717, in save
    force_update=force_update, update_fields=update_fields)
  File "/home/troll/.local/share/virtualenvs/backend-ArvMLrc1/lib/python3.6/site-packages/django/db/models/base.py", line 747, in save_base
    updated = self._save_table(raw, cls, force_insert, force_update, using, update_fields)
  File "/home/troll/.local/share/virtualenvs/backend-ArvMLrc1/lib/python3.6/site-packages/django/db/models/base.py", line 830, in _save_table
    result = self._do_insert(cls._base_manager, using, fields, update_pk, raw)
  File "/home/troll/.local/share/virtualenvs/backend-ArvMLrc1/lib/python3.6/site-packages/django/db/models/base.py", line 868, in _do_insert
    using=using, raw=raw)
  File "/home/troll/.local/share/virtualenvs/backend-ArvMLrc1/lib/python3.6/site-packages/django/db/models/manager.py", line 82, in manager_method
    return getattr(self.get_queryset(), name)(*args, **kwargs)
  File "/home/troll/.local/share/virtualenvs/backend-ArvMLrc1/lib/python3.6/site-packages/django/db/models/query.py", line 1133, in _insert
    return query.get_compiler(using=using).execute_sql(return_id)
  File "/home/troll/.local/share/virtualenvs/backend-ArvMLrc1/lib/python3.6/site-packages/django/db/models/sql/compiler.py", line 1285, in execute_sql
    cursor.execute(sql, params)
  File "/home/troll/.local/share/virtualenvs/backend-ArvMLrc1/lib/python3.6/site-packages/django/db/backends/utils.py", line 100, in execute
    return super().execute(sql, params)
  File "/home/troll/.local/share/virtualenvs/backend-ArvMLrc1/lib/python3.6/site-packages/django/db/backends/utils.py", line 68, in execute
    return self._execute_with_wrappers(sql, params, many=False, executor=self._execute)
  File "/home/troll/.local/share/virtualenvs/backend-ArvMLrc1/lib/python3.6/site-packages/django/db/backends/utils.py", line 77, in _execute_with_wrappers
    return executor(sql, params, many, context)
  File "/home/troll/.local/share/virtualenvs/backend-ArvMLrc1/lib/python3.6/site-packages/django/db/backends/utils.py", line 85, in _execute
    return self.cursor.execute(sql, params)
  File "/home/troll/.local/share/virtualenvs/backend-ArvMLrc1/lib/python3.6/site-packages/django/db/utils.py", line 89, in __exit__
    raise dj_exc_value.with_traceback(traceback) from exc_value
  File "/home/troll/.local/share/virtualenvs/backend-ArvMLrc1/lib/python3.6/site-packages/django/db/backends/utils.py", line 85, in _execute
    return self.cursor.execute(sql, params)
django.db.utils.IntegrityError: duplicate key value violates unique constraint "auth_user_username_key"
DETAIL:  Key (username)=(82T1jQ) already exists.

DEBUG:jwt_auth.views: OrderedDict([('first_name', 'Ashish'), ('last_name', ''), ('email', 'ash2shukla@gmail.co'), ('mobile', '9818611162'), ('business_name', 'Aate hai'), ('password', 'Tadpatehai'), ('otp', '355268')]) (2018-08-27 02:28:11; views.py:57)
ERROR:django.request: Internal Server Error: /auth/verify-otp/ (2018-08-27 02:28:20; log.py:228)
Traceback (most recent call last):
  File "/home/troll/.local/share/virtualenvs/backend-ArvMLrc1/lib/python3.6/site-packages/django/core/handlers/exception.py", line 34, in inner
    response = get_response(request)
  File "/home/troll/.local/share/virtualenvs/backend-ArvMLrc1/lib/python3.6/site-packages/django/core/handlers/base.py", line 126, in _get_response
    response = self.process_exception_by_middleware(e, request)
  File "/home/troll/.local/share/virtualenvs/backend-ArvMLrc1/lib/python3.6/site-packages/django/core/handlers/base.py", line 124, in _get_response
    response = wrapped_callback(request, *callback_args, **callback_kwargs)
  File "/home/troll/.local/share/virtualenvs/backend-ArvMLrc1/lib/python3.6/site-packages/django/views/decorators/csrf.py", line 54, in wrapped_view
    return view_func(*args, **kwargs)
  File "/home/troll/.local/share/virtualenvs/backend-ArvMLrc1/lib/python3.6/site-packages/django/views/generic/base.py", line 68, in view
    return self.dispatch(request, *args, **kwargs)
  File "/home/troll/.local/share/virtualenvs/backend-ArvMLrc1/lib/python3.6/site-packages/rest_framework/views.py", line 483, in dispatch
    response = self.handle_exception(exc)
  File "/home/troll/.local/share/virtualenvs/backend-ArvMLrc1/lib/python3.6/site-packages/rest_framework/views.py", line 443, in handle_exception
    self.raise_uncaught_exception(exc)
  File "/home/troll/.local/share/virtualenvs/backend-ArvMLrc1/lib/python3.6/site-packages/rest_framework/views.py", line 480, in dispatch
    response = handler(request, *args, **kwargs)
  File "/home/troll/procom-com/backend/procom_backend/jwt_auth/views.py", line 117, in post
    user = create_user_with_profile(validated_data)
  File "/home/troll/procom-com/backend/procom_backend/jwt_auth/utils.py", line 49, in create_user_with_profile
    gstin=validated_data['gstin'],
KeyError: 'gstin'
ERROR:django.request: Internal Server Error: /auth/verify-otp/ (2018-08-27 02:28:20; log.py:228)
Traceback (most recent call last):
  File "/home/troll/.local/share/virtualenvs/backend-ArvMLrc1/lib/python3.6/site-packages/django/db/backends/utils.py", line 85, in _execute
    return self.cursor.execute(sql, params)
psycopg2.IntegrityError: duplicate key value violates unique constraint "auth_user_username_key"
DETAIL:  Key (username)=(5yVIkt) already exists.


The above exception was the direct cause of the following exception:

Traceback (most recent call last):
  File "/home/troll/.local/share/virtualenvs/backend-ArvMLrc1/lib/python3.6/site-packages/django/core/handlers/exception.py", line 34, in inner
    response = get_response(request)
  File "/home/troll/.local/share/virtualenvs/backend-ArvMLrc1/lib/python3.6/site-packages/django/core/handlers/base.py", line 126, in _get_response
    response = self.process_exception_by_middleware(e, request)
  File "/home/troll/.local/share/virtualenvs/backend-ArvMLrc1/lib/python3.6/site-packages/django/core/handlers/base.py", line 124, in _get_response
    response = wrapped_callback(request, *callback_args, **callback_kwargs)
  File "/home/troll/.local/share/virtualenvs/backend-ArvMLrc1/lib/python3.6/site-packages/django/views/decorators/csrf.py", line 54, in wrapped_view
    return view_func(*args, **kwargs)
  File "/home/troll/.local/share/virtualenvs/backend-ArvMLrc1/lib/python3.6/site-packages/django/views/generic/base.py", line 68, in view
    return self.dispatch(request, *args, **kwargs)
  File "/home/troll/.local/share/virtualenvs/backend-ArvMLrc1/lib/python3.6/site-packages/rest_framework/views.py", line 483, in dispatch
    response = self.handle_exception(exc)
  File "/home/troll/.local/share/virtualenvs/backend-ArvMLrc1/lib/python3.6/site-packages/rest_framework/views.py", line 443, in handle_exception
    self.raise_uncaught_exception(exc)
  File "/home/troll/.local/share/virtualenvs/backend-ArvMLrc1/lib/python3.6/site-packages/rest_framework/views.py", line 480, in dispatch
    response = handler(request, *args, **kwargs)
  File "/home/troll/procom-com/backend/procom_backend/jwt_auth/views.py", line 117, in post
    user = create_user_with_profile(validated_data)
  File "/home/troll/procom-com/backend/procom_backend/jwt_auth/utils.py", line 47, in create_user_with_profile
    user.save()
  File "/home/troll/.local/share/virtualenvs/backend-ArvMLrc1/lib/python3.6/site-packages/django/contrib/auth/base_user.py", line 73, in save
    super().save(*args, **kwargs)
  File "/home/troll/.local/share/virtualenvs/backend-ArvMLrc1/lib/python3.6/site-packages/django/db/models/base.py", line 717, in save
    force_update=force_update, update_fields=update_fields)
  File "/home/troll/.local/share/virtualenvs/backend-ArvMLrc1/lib/python3.6/site-packages/django/db/models/base.py", line 747, in save_base
    updated = self._save_table(raw, cls, force_insert, force_update, using, update_fields)
  File "/home/troll/.local/share/virtualenvs/backend-ArvMLrc1/lib/python3.6/site-packages/django/db/models/base.py", line 830, in _save_table
    result = self._do_insert(cls._base_manager, using, fields, update_pk, raw)
  File "/home/troll/.local/share/virtualenvs/backend-ArvMLrc1/lib/python3.6/site-packages/django/db/models/base.py", line 868, in _do_insert
    using=using, raw=raw)
  File "/home/troll/.local/share/virtualenvs/backend-ArvMLrc1/lib/python3.6/site-packages/django/db/models/manager.py", line 82, in manager_method
    return getattr(self.get_queryset(), name)(*args, **kwargs)
  File "/home/troll/.local/share/virtualenvs/backend-ArvMLrc1/lib/python3.6/site-packages/django/db/models/query.py", line 1133, in _insert
    return query.get_compiler(using=using).execute_sql(return_id)
  File "/home/troll/.local/share/virtualenvs/backend-ArvMLrc1/lib/python3.6/site-packages/django/db/models/sql/compiler.py", line 1285, in execute_sql
    cursor.execute(sql, params)
  File "/home/troll/.local/share/virtualenvs/backend-ArvMLrc1/lib/python3.6/site-packages/django/db/backends/utils.py", line 100, in execute
    return super().execute(sql, params)
  File "/home/troll/.local/share/virtualenvs/backend-ArvMLrc1/lib/python3.6/site-packages/django/db/backends/utils.py", line 68, in execute
    return self._execute_with_wrappers(sql, params, many=False, executor=self._execute)
  File "/home/troll/.local/share/virtualenvs/backend-ArvMLrc1/lib/python3.6/site-packages/django/db/backends/utils.py", line 77, in _execute_with_wrappers
    return executor(sql, params, many, context)
  File "/home/troll/.local/share/virtualenvs/backend-ArvMLrc1/lib/python3.6/site-packages/django/db/backends/utils.py", line 85, in _execute
    return self.cursor.execute(sql, params)
  File "/home/troll/.local/share/virtualenvs/backend-ArvMLrc1/lib/python3.6/site-packages/django/db/utils.py", line 89, in __exit__
    raise dj_exc_value.with_traceback(traceback) from exc_value
  File "/home/troll/.local/share/virtualenvs/backend-ArvMLrc1/lib/python3.6/site-packages/django/db/backends/utils.py", line 85, in _execute
    return self.cursor.execute(sql, params)
django.db.utils.IntegrityError: duplicate key value violates unique constraint "auth_user_username_key"
DETAIL:  Key (username)=(5yVIkt) already exists.

ERROR:django.request: Internal Server Error: /auth/verify-otp/ (2018-08-27 02:28:20; log.py:228)
Traceback (most recent call last):
  File "/home/troll/.local/share/virtualenvs/backend-ArvMLrc1/lib/python3.6/site-packages/django/db/backends/utils.py", line 85, in _execute
    return self.cursor.execute(sql, params)
psycopg2.IntegrityError: duplicate key value violates unique constraint "auth_user_username_key"
DETAIL:  Key (username)=(5yVIkt) already exists.


The above exception was the direct cause of the following exception:

Traceback (most recent call last):
  File "/home/troll/.local/share/virtualenvs/backend-ArvMLrc1/lib/python3.6/site-packages/django/core/handlers/exception.py", line 34, in inner
    response = get_response(request)
  File "/home/troll/.local/share/virtualenvs/backend-ArvMLrc1/lib/python3.6/site-packages/django/core/handlers/base.py", line 126, in _get_response
    response = self.process_exception_by_middleware(e, request)
  File "/home/troll/.local/share/virtualenvs/backend-ArvMLrc1/lib/python3.6/site-packages/django/core/handlers/base.py", line 124, in _get_response
    response = wrapped_callback(request, *callback_args, **callback_kwargs)
  File "/home/troll/.local/share/virtualenvs/backend-ArvMLrc1/lib/python3.6/site-packages/django/views/decorators/csrf.py", line 54, in wrapped_view
    return view_func(*args, **kwargs)
  File "/home/troll/.local/share/virtualenvs/backend-ArvMLrc1/lib/python3.6/site-packages/django/views/generic/base.py", line 68, in view
    return self.dispatch(request, *args, **kwargs)
  File "/home/troll/.local/share/virtualenvs/backend-ArvMLrc1/lib/python3.6/site-packages/rest_framework/views.py", line 483, in dispatch
    response = self.handle_exception(exc)
  File "/home/troll/.local/share/virtualenvs/backend-ArvMLrc1/lib/python3.6/site-packages/rest_framework/views.py", line 443, in handle_exception
    self.raise_uncaught_exception(exc)
  File "/home/troll/.local/share/virtualenvs/backend-ArvMLrc1/lib/python3.6/site-packages/rest_framework/views.py", line 480, in dispatch
    response = handler(request, *args, **kwargs)
  File "/home/troll/procom-com/backend/procom_backend/jwt_auth/views.py", line 117, in post
    user = create_user_with_profile(validated_data)
  File "/home/troll/procom-com/backend/procom_backend/jwt_auth/utils.py", line 47, in create_user_with_profile
    user.save()
  File "/home/troll/.local/share/virtualenvs/backend-ArvMLrc1/lib/python3.6/site-packages/django/contrib/auth/base_user.py", line 73, in save
    super().save(*args, **kwargs)
  File "/home/troll/.local/share/virtualenvs/backend-ArvMLrc1/lib/python3.6/site-packages/django/db/models/base.py", line 717, in save
    force_update=force_update, update_fields=update_fields)
  File "/home/troll/.local/share/virtualenvs/backend-ArvMLrc1/lib/python3.6/site-packages/django/db/models/base.py", line 747, in save_base
    updated = self._save_table(raw, cls, force_insert, force_update, using, update_fields)
  File "/home/troll/.local/share/virtualenvs/backend-ArvMLrc1/lib/python3.6/site-packages/django/db/models/base.py", line 830, in _save_table
    result = self._do_insert(cls._base_manager, using, fields, update_pk, raw)
  File "/home/troll/.local/share/virtualenvs/backend-ArvMLrc1/lib/python3.6/site-packages/django/db/models/base.py", line 868, in _do_insert
    using=using, raw=raw)
  File "/home/troll/.local/share/virtualenvs/backend-ArvMLrc1/lib/python3.6/site-packages/django/db/models/manager.py", line 82, in manager_method
    return getattr(self.get_queryset(), name)(*args, **kwargs)
  File "/home/troll/.local/share/virtualenvs/backend-ArvMLrc1/lib/python3.6/site-packages/django/db/models/query.py", line 1133, in _insert
    return query.get_compiler(using=using).execute_sql(return_id)
  File "/home/troll/.local/share/virtualenvs/backend-ArvMLrc1/lib/python3.6/site-packages/django/db/models/sql/compiler.py", line 1285, in execute_sql
    cursor.execute(sql, params)
  File "/home/troll/.local/share/virtualenvs/backend-ArvMLrc1/lib/python3.6/site-packages/django/db/backends/utils.py", line 100, in execute
    return super().execute(sql, params)
  File "/home/troll/.local/share/virtualenvs/backend-ArvMLrc1/lib/python3.6/site-packages/django/db/backends/utils.py", line 68, in execute
    return self._execute_with_wrappers(sql, params, many=False, executor=self._execute)
  File "/home/troll/.local/share/virtualenvs/backend-ArvMLrc1/lib/python3.6/site-packages/django/db/backends/utils.py", line 77, in _execute_with_wrappers
    return executor(sql, params, many, context)
  File "/home/troll/.local/share/virtualenvs/backend-ArvMLrc1/lib/python3.6/site-packages/django/db/backends/utils.py", line 85, in _execute
    return self.cursor.execute(sql, params)
  File "/home/troll/.local/share/virtualenvs/backend-ArvMLrc1/lib/python3.6/site-packages/django/db/utils.py", line 89, in __exit__
    raise dj_exc_value.with_traceback(traceback) from exc_value
  File "/home/troll/.local/share/virtualenvs/backend-ArvMLrc1/lib/python3.6/site-packages/django/db/backends/utils.py", line 85, in _execute
    return self.cursor.execute(sql, params)
django.db.utils.IntegrityError: duplicate key value violates unique constraint "auth_user_username_key"
DETAIL:  Key (username)=(5yVIkt) already exists.

ERROR:django.request: Internal Server Error: /auth/verify-otp/ (2018-08-27 02:28:21; log.py:228)
Traceback (most recent call last):
  File "/home/troll/.local/share/virtualenvs/backend-ArvMLrc1/lib/python3.6/site-packages/django/db/backends/utils.py", line 85, in _execute
    return self.cursor.execute(sql, params)
psycopg2.IntegrityError: duplicate key value violates unique constraint "auth_user_username_key"
DETAIL:  Key (username)=(5yVIkt) already exists.


The above exception was the direct cause of the following exception:

Traceback (most recent call last):
  File "/home/troll/.local/share/virtualenvs/backend-ArvMLrc1/lib/python3.6/site-packages/django/core/handlers/exception.py", line 34, in inner
    response = get_response(request)
  File "/home/troll/.local/share/virtualenvs/backend-ArvMLrc1/lib/python3.6/site-packages/django/core/handlers/base.py", line 126, in _get_response
    response = self.process_exception_by_middleware(e, request)
  File "/home/troll/.local/share/virtualenvs/backend-ArvMLrc1/lib/python3.6/site-packages/django/core/handlers/base.py", line 124, in _get_response
    response = wrapped_callback(request, *callback_args, **callback_kwargs)
  File "/home/troll/.local/share/virtualenvs/backend-ArvMLrc1/lib/python3.6/site-packages/django/views/decorators/csrf.py", line 54, in wrapped_view
    return view_func(*args, **kwargs)
  File "/home/troll/.local/share/virtualenvs/backend-ArvMLrc1/lib/python3.6/site-packages/django/views/generic/base.py", line 68, in view
    return self.dispatch(request, *args, **kwargs)
  File "/home/troll/.local/share/virtualenvs/backend-ArvMLrc1/lib/python3.6/site-packages/rest_framework/views.py", line 483, in dispatch
    response = self.handle_exception(exc)
  File "/home/troll/.local/share/virtualenvs/backend-ArvMLrc1/lib/python3.6/site-packages/rest_framework/views.py", line 443, in handle_exception
    self.raise_uncaught_exception(exc)
  File "/home/troll/.local/share/virtualenvs/backend-ArvMLrc1/lib/python3.6/site-packages/rest_framework/views.py", line 480, in dispatch
    response = handler(request, *args, **kwargs)
  File "/home/troll/procom-com/backend/procom_backend/jwt_auth/views.py", line 117, in post
    user = create_user_with_profile(validated_data)
  File "/home/troll/procom-com/backend/procom_backend/jwt_auth/utils.py", line 47, in create_user_with_profile
    user.save()
  File "/home/troll/.local/share/virtualenvs/backend-ArvMLrc1/lib/python3.6/site-packages/django/contrib/auth/base_user.py", line 73, in save
    super().save(*args, **kwargs)
  File "/home/troll/.local/share/virtualenvs/backend-ArvMLrc1/lib/python3.6/site-packages/django/db/models/base.py", line 717, in save
    force_update=force_update, update_fields=update_fields)
  File "/home/troll/.local/share/virtualenvs/backend-ArvMLrc1/lib/python3.6/site-packages/django/db/models/base.py", line 747, in save_base
    updated = self._save_table(raw, cls, force_insert, force_update, using, update_fields)
  File "/home/troll/.local/share/virtualenvs/backend-ArvMLrc1/lib/python3.6/site-packages/django/db/models/base.py", line 830, in _save_table
    result = self._do_insert(cls._base_manager, using, fields, update_pk, raw)
  File "/home/troll/.local/share/virtualenvs/backend-ArvMLrc1/lib/python3.6/site-packages/django/db/models/base.py", line 868, in _do_insert
    using=using, raw=raw)
  File "/home/troll/.local/share/virtualenvs/backend-ArvMLrc1/lib/python3.6/site-packages/django/db/models/manager.py", line 82, in manager_method
    return getattr(self.get_queryset(), name)(*args, **kwargs)
  File "/home/troll/.local/share/virtualenvs/backend-ArvMLrc1/lib/python3.6/site-packages/django/db/models/query.py", line 1133, in _insert
    return query.get_compiler(using=using).execute_sql(return_id)
  File "/home/troll/.local/share/virtualenvs/backend-ArvMLrc1/lib/python3.6/site-packages/django/db/models/sql/compiler.py", line 1285, in execute_sql
    cursor.execute(sql, params)
  File "/home/troll/.local/share/virtualenvs/backend-ArvMLrc1/lib/python3.6/site-packages/django/db/backends/utils.py", line 100, in execute
    return super().execute(sql, params)
  File "/home/troll/.local/share/virtualenvs/backend-ArvMLrc1/lib/python3.6/site-packages/django/db/backends/utils.py", line 68, in execute
    return self._execute_with_wrappers(sql, params, many=False, executor=self._execute)
  File "/home/troll/.local/share/virtualenvs/backend-ArvMLrc1/lib/python3.6/site-packages/django/db/backends/utils.py", line 77, in _execute_with_wrappers
    return executor(sql, params, many, context)
  File "/home/troll/.local/share/virtualenvs/backend-ArvMLrc1/lib/python3.6/site-packages/django/db/backends/utils.py", line 85, in _execute
    return self.cursor.execute(sql, params)
  File "/home/troll/.local/share/virtualenvs/backend-ArvMLrc1/lib/python3.6/site-packages/django/db/utils.py", line 89, in __exit__
    raise dj_exc_value.with_traceback(traceback) from exc_value
  File "/home/troll/.local/share/virtualenvs/backend-ArvMLrc1/lib/python3.6/site-packages/django/db/backends/utils.py", line 85, in _execute
    return self.cursor.execute(sql, params)
django.db.utils.IntegrityError: duplicate key value violates unique constraint "auth_user_username_key"
DETAIL:  Key (username)=(5yVIkt) already exists.

DEBUG:asyncio: Using selector: EpollSelector (2018-08-27 17:56:40; selector_events.py:65)
DEBUG:asyncio: Using selector: EpollSelector (2018-08-27 17:56:42; selector_events.py:65)
INFO:daphne.server: HTTP/2 support enabled (2018-08-27 17:56:48; server.py:103)
INFO:daphne.server: Configuring endpoint tcp:port=8000:interface=0.0.0.0 (2018-08-27 17:56:48; server.py:112)
INFO:daphne.server: Listening on TCP address 0.0.0.0:8000 (2018-08-27 17:56:48; server.py:143)
WARNING:daphne.server: Application instance <Task pending coro=<AsgiHandler.__call__() running at /home/troll/.local/share/virtualenvs/backend-ArvMLrc1/lib/python3.6/site-packages/channels/http.py:180> wait_for=<Future pending cb=[<TaskWakeupMethWrapper object at 0x7fe753fb8618>()]>> for connection <WebRequest at 0x7fe75271bbe0 method=POST uri=/auth/does-email-exist/ clientproto=HTTP/1.1> took too long to shut down and was killed. (2018-08-27 17:59:13; server.py:223)
DEBUG:jwt_auth.views: OrderedDict([('first_name', 'Ashish'), ('last_name', ''), ('email', 'ash2shukla@gmail.lwl'), ('mobile', '9818611162'), ('business_name', '123 ting'), ('password', 'Tingtong'), ('otp', '325536')]) (2018-08-27 17:59:23; views.py:57)
ERROR:django.request: Internal Server Error: /auth/verify-otp/ (2018-08-27 17:59:36; log.py:228)
Traceback (most recent call last):
  File "/home/troll/.local/share/virtualenvs/backend-ArvMLrc1/lib/python3.6/site-packages/django/core/handlers/exception.py", line 34, in inner
    response = get_response(request)
  File "/home/troll/.local/share/virtualenvs/backend-ArvMLrc1/lib/python3.6/site-packages/django/core/handlers/base.py", line 126, in _get_response
    response = self.process_exception_by_middleware(e, request)
  File "/home/troll/.local/share/virtualenvs/backend-ArvMLrc1/lib/python3.6/site-packages/django/core/handlers/base.py", line 124, in _get_response
    response = wrapped_callback(request, *callback_args, **callback_kwargs)
  File "/home/troll/.local/share/virtualenvs/backend-ArvMLrc1/lib/python3.6/site-packages/django/views/decorators/csrf.py", line 54, in wrapped_view
    return view_func(*args, **kwargs)
  File "/home/troll/.local/share/virtualenvs/backend-ArvMLrc1/lib/python3.6/site-packages/django/views/generic/base.py", line 68, in view
    return self.dispatch(request, *args, **kwargs)
  File "/home/troll/.local/share/virtualenvs/backend-ArvMLrc1/lib/python3.6/site-packages/rest_framework/views.py", line 483, in dispatch
    response = self.handle_exception(exc)
  File "/home/troll/.local/share/virtualenvs/backend-ArvMLrc1/lib/python3.6/site-packages/rest_framework/views.py", line 443, in handle_exception
    self.raise_uncaught_exception(exc)
  File "/home/troll/.local/share/virtualenvs/backend-ArvMLrc1/lib/python3.6/site-packages/rest_framework/views.py", line 480, in dispatch
    response = handler(request, *args, **kwargs)
  File "/home/troll/procom-com/backend/procom_backend/jwt_auth/views.py", line 117, in post
    user = create_user_with_profile(validated_data)
  File "/home/troll/procom-com/backend/procom_backend/jwt_auth/utils.py", line 49, in create_user_with_profile
    gstin=validated_data['gstin'],
KeyError: 'gstin'
DEBUG:asyncio: Using selector: EpollSelector (2018-08-27 18:00:34; selector_events.py:65)
INFO:daphne.server: HTTP/2 support enabled (2018-08-27 18:00:36; server.py:103)
INFO:daphne.server: Configuring endpoint tcp:port=8000:interface=0.0.0.0 (2018-08-27 18:00:36; server.py:112)
INFO:daphne.server: Listening on TCP address 0.0.0.0:8000 (2018-08-27 18:00:36; server.py:143)
DEBUG:asyncio: Using selector: EpollSelector (2018-08-27 18:00:44; selector_events.py:65)
INFO:daphne.server: HTTP/2 support enabled (2018-08-27 18:00:45; server.py:103)
INFO:daphne.server: Configuring endpoint tcp:port=8000:interface=0.0.0.0 (2018-08-27 18:00:45; server.py:112)
INFO:daphne.server: Listening on TCP address 0.0.0.0:8000 (2018-08-27 18:00:45; server.py:143)
DEBUG:asyncio: Using selector: EpollSelector (2018-08-27 20:47:31; selector_events.py:65)
DEBUG:asyncio: Using selector: EpollSelector (2018-08-27 20:47:34; selector_events.py:65)
INFO:daphne.server: HTTP/2 support enabled (2018-08-27 20:47:39; server.py:103)
INFO:daphne.server: Configuring endpoint tcp:port=8000:interface=0.0.0.0 (2018-08-27 20:47:39; server.py:112)
INFO:daphne.server: Listening on TCP address 0.0.0.0:8000 (2018-08-27 20:47:39; server.py:143)
DEBUG:jwt_auth.views: OrderedDict([('first_name', 'Ashish'), ('last_name', ''), ('email', 'ash2shukla@gmail.ci'), ('mobile', '9818611162'), ('business_name', 'Loler'), ('password', 'Tingtong'), ('otp', '078590')]) (2018-08-27 20:48:24; views.py:57)
DEBUG:jwt_auth.utils: SIGNIN - user: fY0vPy session: urz2p6l82iTX0WkcGGIVEcMeVjk3jApy refresh_token: LzENprZTm8KSuHvoqdOWnLHhdhnGsjsC jti: BoIBLCuwpBME9rl9wkEsMcJGJtUUkV4k (2018-08-27 20:48:38; utils.py:86)
DEBUG:jwt_auth.views: SIGNOUT user fY0vPy at session {'refresh_token': 'LzENprZTm8KSuHvoqdOWnLHhdhnGsjsC', 'jti': 'BoIBLCuwpBME9rl9wkEsMcJGJtUUkV4k', 'origin_at': 1535363318.461666, 'refreshed_at': 1535363318.461666} (2018-08-27 20:50:02; views.py:399)
DEBUG:asyncio: Using selector: EpollSelector (2018-08-28 07:27:25; selector_events.py:65)
DEBUG:asyncio: Using selector: EpollSelector (2018-08-28 07:27:28; selector_events.py:65)
INFO:daphne.server: HTTP/2 support enabled (2018-08-28 07:27:34; server.py:103)
INFO:daphne.server: Configuring endpoint tcp:port=8000:interface=0.0.0.0 (2018-08-28 07:27:34; server.py:112)
INFO:daphne.server: Listening on TCP address 0.0.0.0:8000 (2018-08-28 07:27:34; server.py:143)
DEBUG:aioredis: Parsing Redis URI 'redis://:procom321@localhost:6379/0' (2018-08-28 07:27:39; connection.py:78)
DEBUG:aioredis: Creating tcp connection to ('localhost', 6379) (2018-08-28 07:27:39; connection.py:104)
DEBUG:jwt_auth.consumers: sent QR to channel_id: specific.UygjpjZj!QgmvWsbTjLVc (2018-08-28 07:27:39; consumers.py:65)
DEBUG:jwt_auth.consumers: sent QR to channel_id: specific.UygjpjZj!QgmvWsbTjLVc (2018-08-28 07:27:43; consumers.py:65)
DEBUG:jwt_auth.consumers: sent QR to channel_id: specific.UygjpjZj!QgmvWsbTjLVc (2018-08-28 07:27:48; consumers.py:65)
DEBUG:jwt_auth.consumers: sent QR to channel_id: specific.UygjpjZj!QgmvWsbTjLVc (2018-08-28 07:27:53; consumers.py:65)
DEBUG:jwt_auth.consumers: sent QR to channel_id: specific.UygjpjZj!QgmvWsbTjLVc (2018-08-28 07:27:58; consumers.py:65)
DEBUG:jwt_auth.consumers: sent QR to channel_id: specific.UygjpjZj!QgmvWsbTjLVc (2018-08-28 07:28:03; consumers.py:65)
DEBUG:aioredis: Cancelling waiter (<Future cancelled>, [None, None]) (2018-08-28 07:28:05; connection.py:370)
DEBUG:aioredis: Waiter future is already done <Future cancelled> (2018-08-28 07:28:05; util.py:122)
DEBUG:asyncio: Using selector: EpollSelector (2018-08-28 07:32:00; selector_events.py:65)
DEBUG:asyncio: Using selector: EpollSelector (2018-08-28 07:32:01; selector_events.py:65)
INFO:daphne.server: HTTP/2 support enabled (2018-08-28 07:32:02; server.py:103)
INFO:daphne.server: Configuring endpoint tcp:port=8000:interface=0.0.0.0 (2018-08-28 07:32:02; server.py:112)
INFO:daphne.server: Listening on TCP address 0.0.0.0:8000 (2018-08-28 07:32:02; server.py:143)
DEBUG:aioredis: Parsing Redis URI 'redis://:procom321@localhost:6379/0' (2018-08-28 07:32:06; connection.py:78)
DEBUG:aioredis: Creating tcp connection to ('localhost', 6379) (2018-08-28 07:32:06; connection.py:104)
DEBUG:jwt_auth.consumers: sent QR to channel_id: specific.iOujMrJY!mRndHlKfVSpI (2018-08-28 07:32:06; consumers.py:65)
DEBUG:jwt_auth.consumers: sent QR to channel_id: specific.iOujMrJY!mRndHlKfVSpI (2018-08-28 07:32:11; consumers.py:65)
DEBUG:aioredis: Cancelling waiter (<Future cancelled>, [None, None]) (2018-08-28 07:32:13; connection.py:370)
DEBUG:aioredis: Waiter future is already done <Future cancelled> (2018-08-28 07:32:13; util.py:122)
DEBUG:jwt_auth.utils: SIGNIN - user: 35ccVY session: LSgFFCgI4EdKBcsuSDh0Ln9AcM6UQXoX refresh_token: Nli4tDM6rpFGejOKRVmFpssPhDC3QauE jti: aFepb9aNROTZ3s6Ik7p2bc3NfxIdxUwT (2018-08-28 07:32:28; utils.py:86)
DEBUG:jwt_auth.views: SIGNOUT user 35ccVY at session {'refresh_token': 'Nli4tDM6rpFGejOKRVmFpssPhDC3QauE', 'jti': 'aFepb9aNROTZ3s6Ik7p2bc3NfxIdxUwT', 'origin_at': 1535401948.644581, 'refreshed_at': 1535401948.644581} (2018-08-28 07:33:42; views.py:399)
DEBUG:jwt_auth.views: OrderedDict([('first_name', 'Ashish'), ('last_name', 'Pashish'), ('email', 'ash3shukla@gmail.com'), ('mobile', '9818611163'), ('business_name', 'TIntong'), ('password', 'Pingpong'), ('otp', '020507')]) (2018-08-28 07:33:42; views.py:57)
DEBUG:jwt_auth.utils: SIGNIN - user: Z1wU4i session: uEwuL1INmLXiO4fOhnV8b7OfBbuTpGvo refresh_token: eh69TJqKvuXs9hdhS7PGscCwHIaGbkca jti: JoYSGerlDGTsCpOi9nKhzCmOyraj5OVg (2018-08-28 07:33:56; utils.py:86)
DEBUG:jwt_auth.views: SIGNOUT user Z1wU4i at session {'refresh_token': 'eh69TJqKvuXs9hdhS7PGscCwHIaGbkca', 'jti': 'JoYSGerlDGTsCpOi9nKhzCmOyraj5OVg', 'origin_at': 1535402036.9735, 'refreshed_at': 1535402036.9735} (2018-08-28 07:33:59; views.py:399)
DEBUG:aioredis: Parsing Redis URI 'redis://:procom321@localhost:6379/0' (2018-08-28 07:34:08; connection.py:78)
DEBUG:aioredis: Creating tcp connection to ('localhost', 6379) (2018-08-28 07:34:08; connection.py:104)
DEBUG:jwt_auth.consumers: sent QR to channel_id: specific.iOujMrJY!tXnywJDZSzSo (2018-08-28 07:34:08; consumers.py:65)
DEBUG:jwt_auth.consumers: sent QR to channel_id: specific.iOujMrJY!tXnywJDZSzSo (2018-08-28 07:34:13; consumers.py:65)
DEBUG:jwt_auth.consumers: sent QR to channel_id: specific.iOujMrJY!tXnywJDZSzSo (2018-08-28 07:34:18; consumers.py:65)
DEBUG:jwt_auth.consumers: sent QR to channel_id: specific.iOujMrJY!tXnywJDZSzSo (2018-08-28 07:34:23; consumers.py:65)
DEBUG:jwt_auth.consumers: sent QR to channel_id: specific.iOujMrJY!tXnywJDZSzSo (2018-08-28 07:34:28; consumers.py:65)
DEBUG:jwt_auth.consumers: sent QR to channel_id: specific.iOujMrJY!SfSoYGiZtknq (2018-08-28 07:34:29; consumers.py:65)
DEBUG:jwt_auth.consumers: sent QR to channel_id: specific.iOujMrJY!tXnywJDZSzSo (2018-08-28 07:34:33; consumers.py:65)
DEBUG:jwt_auth.consumers: sent QR to channel_id: specific.iOujMrJY!SfSoYGiZtknq (2018-08-28 07:34:34; consumers.py:65)
DEBUG:jwt_auth.consumers: sent QR to channel_id: specific.iOujMrJY!tXnywJDZSzSo (2018-08-28 07:34:38; consumers.py:65)
DEBUG:jwt_auth.consumers: sent QR to channel_id: specific.iOujMrJY!SfSoYGiZtknq (2018-08-28 07:34:39; consumers.py:65)
DEBUG:jwt_auth.consumers: sent QR to channel_id: specific.iOujMrJY!tXnywJDZSzSo (2018-08-28 07:34:43; consumers.py:65)
DEBUG:jwt_auth.consumers: sent QR to channel_id: specific.iOujMrJY!tXnywJDZSzSo (2018-08-28 07:34:48; consumers.py:65)
DEBUG:jwt_auth.consumers: sent QR to channel_id: specific.iOujMrJY!TZcFnACOrBCe (2018-08-28 07:34:51; consumers.py:65)
DEBUG:jwt_auth.consumers: sent QR to channel_id: specific.iOujMrJY!tXnywJDZSzSo (2018-08-28 07:34:53; consumers.py:65)
DEBUG:jwt_auth.consumers: sent QR to channel_id: specific.iOujMrJY!TZcFnACOrBCe (2018-08-28 07:34:56; consumers.py:65)
DEBUG:jwt_auth.consumers: sent QR to channel_id: specific.iOujMrJY!tXnywJDZSzSo (2018-08-28 07:34:58; consumers.py:65)
DEBUG:jwt_auth.consumers: sent QR to channel_id: specific.iOujMrJY!TZcFnACOrBCe (2018-08-28 07:35:01; consumers.py:65)
DEBUG:jwt_auth.consumers: sent QR to channel_id: specific.iOujMrJY!tXnywJDZSzSo (2018-08-28 07:35:03; consumers.py:65)
DEBUG:jwt_auth.consumers: sent QR to channel_id: specific.iOujMrJY!TZcFnACOrBCe (2018-08-28 07:35:06; consumers.py:65)
DEBUG:jwt_auth.consumers: sent QR to channel_id: specific.iOujMrJY!tXnywJDZSzSo (2018-08-28 07:35:08; consumers.py:65)
DEBUG:jwt_auth.consumers: sent QR to channel_id: specific.iOujMrJY!TZcFnACOrBCe (2018-08-28 07:35:11; consumers.py:65)
DEBUG:jwt_auth.consumers: sent QR to channel_id: specific.iOujMrJY!tXnywJDZSzSo (2018-08-28 07:35:13; consumers.py:65)
DEBUG:jwt_auth.consumers: sent QR to channel_id: specific.iOujMrJY!tXnywJDZSzSo (2018-08-28 07:35:18; consumers.py:65)
DEBUG:jwt_auth.consumers: sent QR to channel_id: specific.iOujMrJY!tXnywJDZSzSo (2018-08-28 07:35:23; consumers.py:65)
